Workbook

Sheet Supuestos
A1: Categoría | B1: Supuesto | C1: Descripción | D1: Fuente
A2: Técnico | B2: Disponibilidad (SLA) | C2: 99.99% Multi-AZ | D2: AWS Well-Architected
B3: Latencia Máxima | C3: 2 segundos | D3: Estándar industria travel
B4: Cumplimiento Legal | C4: Ley 1581 (Protección datos) | D4: Normativa Colombia
B5: Escalabilidad | C5: Miles de usuarios simultáneos | D5: Diseño ASG + Load Balancers
A6: Mercado | B6: TRM | C6: 1 USD = 4.200 COP | D6: Proyección 2025-2026
B7: Adopción Pagos Digitales | C7: Alta en Colombia | D7: Tendencia e-commerce
B8: Crecimiento E-commerce | C8: 15-20% anual | D8: Benchmarks sectoriales
A9: Operacional | B9: Modelo de Trabajo | C9: 100% Remoto (Home Office) | D9: Ahorro 30% vs oficina
B10: Infraestructura IA | C10: vLLM para servir modelos | D10: Optimización de latencia
B11: Arquitectura | C11: Multi-AZ para redundancia | D11: Garantía transacciones críticas
B12: Desarrollo | C12: 6 meses con 3 personas | D12: Estimación Payscale
B13: Periodo Capitalización | C13: Análisis 12 meses | D13: Horizonte inicial
A15: USD | B15: COP
A16: 1 | B16: 4200
A18: Promedio Transacción
A19: 500000

Sheet CAPEX
A1: Componente | B1: Descripción | C1: Costo (COP) | D1: Fuente | E1: Supuesto
A2: Desarrollo MVP | B2: Full-stack (React + Android + Spring Boot) | C2: =(61041889)*3 -> 183125667 | D2: Payscale Colombia | E2: 6 meses de desarrollo con un equipo de 3 personas, incluyendo mantenimiento hasta completar el costo anual.
A3: Legal y Constitución | B3: Registro mercantil | C3: 194000 | D3: Cámara de Comercio Bogotá | E3: Derechos de matrícula de establecimientos, sucursales o agencias según normativa vigente.
B4: RNT | C4: 0 | D4: Ministerio de Comercio, Industria y Turismo | E4: El RNT es completamente gratuito.
B5: Marcas | C5: 1347500 | D5: Superintendencia de Industria y Comercio | E5: Solicitud de registro de marca o lema comercial por una clase, incluyendo modificaciones no sustanciales.
A6: Diseño UI/UX | B6: Identidad visual y prototipado | C6: =26400002/2 -> 13200001 | D6: Payscale Colombia | E6: 6 meses de trabajo en diseño.
A7: Marketing Lanzamiento | B7: Estrategia de adquisición inicial | C7: =3370000*6 -> 20220000 | D7: Marketing CPE | E7: Inversión en pauta durante los primeros 6 meses posteriores al lanzamiento.
A8: TOTAL CAPEX | C8: =SUM(C2:C7) -> 218087168

Sheet Cloud
A1: Servicio AWS | B1: Descripción | C1: Costo Mensual (COP) | D1: Costo Anual (COP) | E1: Fuente | F1: Supuesto
A2: API Gateway | B2: Gestión REST API | C2: =1*Supuestos!$B$16 -> 4200 | D2: =C2*12 -> 50400 | E2: AWS Pricing Calculator | F2: 1 millón de peticiones mensuales
A3: Application Load Balancer | B3: Balanceo de carga en múltiples zonas (Multi-AZ) | C3: =21.1*Supuestos!$B$16 -> 88620 | D3: =C3*12 -> 1063440 | F3: Instancia base + 0.8 LCU bajo modelo de pago por uso
A4: EC2 | B4: Auto Scaling Group para servicios Spring Boot, gestión de reservas, APIs, FastAPI, procesamiento con GPU NVIDIA T4 y predicción de CO2e (RAG) | C4: =12.26*Supuestos!$B$16 -> 51492 | D4: =C4*12 -> 617904 | F4: Reserva a 1 año con mínimo 4 instancias
A5: RDS | B5: Base de datos primaria en configuración Multi-AZ. Instancias adicionales PostgreSQL Multi-AZ. Base de datos para machine learning y vectores (embeddings) | C5: =500*Supuestos!$B$16 -> 2100000 | D5: =C5*12 -> 25200000 | F5: Alta disponibilidad para cargas críticas y almacenamiento de embeddings y metadatos
A6: S3 Buckets | B6: Almacenamiento de media, logs, pesos de modelos y contenido estático de la aplicación | C6: =4.74*Supuestos!$B$16 -> 19908 | D6: =C6*12 -> 238896 | F6: 200 GB de almacenamiento total + transferencia de datos
A7: CloudFront | B7: Red de distribución de contenido (CDN) | C7: =42.5*Supuestos!$B$16 -> 178500 | D7: =C7*12 -> 2142000 | F7: Aproximadamente 500 GB de salida de datos mensual
A8: SNS/SQS | B8: Capa asincrónica para eventos y colas de mensajes | C8: =20.71*Supuestos!$B$16 -> 86982 | D8: =C8*12 -> 1043784 | F8: Hasta 1 millón de mensajes mensuales
A9: CloudWatch | B9: Monitoreo, logs, métricas y alertas | C9: =10*Supuestos!$B$16 -> 42000 | D9: =C9*12 -> 504000 | F9: Incluye retención de logs y dashboards
A10: Lambda | B10: Procesamiento de tickets y archivos PDF | C10: =0.2*Supuestos!$B$16 -> 840 | D10: =C10*12 -> 10080 | F10: 2 millones de ejecuciones mensuales
A11: TOTAL CLOUD | C11: =SUM(C2:C10) -> 2572542 | D11: =SUM(D2:D10) -> 30870504

Sheet AI
A1: Modelo / Servicio | B1: Tipo de Cobro | C1: Costo Mensual (COP) | D1: Costo Anual (COP) | E1: Escenario de Uso | F1: Supuesto
A2: vLLM | B2: Inferencia Local | C2: 0 | D2: 0 | E2: 24/7 Disponible | F2: Licencia abierta; costo absorbido en EC2 AI
A3: Optimización de Modelos | B3: Fine-tuning Interno | C3: 0 | D3: 0 | E3: Equipo MLOps | F3: Ejecutado por personal interno
A4: TOTAL IA | C4: =SUM(C2:C3) -> 0 | D4: =SUM(D2:D3) -> 0

Sheet Transaccional
A1: Concepto | B1: Tipo de Cobro | C1: Volumen Mensual Estimado | D1: Costo Mensual (COP) | E1: Fuente | F1: Supuesto
A2: Pasarela Wompi | B2: Comisión + Tarifa | C2: 500 transacciones | D2: =(((Supuestos!$A$19*0.0265)+700)*1.19)*500 -> 8300250 | E2: Wompi | F2: Por cada transacción procesada
A3: Google Maps API | B3: Por Request | C3: 1,000,000 queries | D3: =2013*Supuestos!$B$16 -> 8454600 | E3: Maps Platform | F3: Autocompletado y rutas
A4: Amadeus API | B4: Por Request | C4: 100,000 búsquedas | D4: =(0.025*100000)*Supuestos!$B$16 -> 10500000 | E4: Amadeus for Developers | F4: Consultas de vuelos y hoteles
A5: Twilio SMS/WhatsApp | B5: Por Mensaje | C5: 100,000 mensajes | D5: =(0.005*100000)*Supuestos!$B$16 -> 2100000 | E5: Twilio | F5: Notificaciones de confirmación
A6: TOTAL TRANSACCIONAL | D6: =SUM(D2:D5) -> 29354850

Sheet OPEX
A1: Categoría | B1: Subcomponente | C1: Costo Mensual (COP) | D1: Costo Anual (COP) | E1: Fuente | F1: Supuesto
A2: Talento | B2: CTO / Líder Técnico | C2: 8000000 | D2: =C2*12 -> 96000000 | E2: Payscale Colombia | F2: Arquitecto AWS + DevOps Senior
B3: MLOps / DevOps | C3: 6600000 | D3: =C3*12 -> 79200000 | F3: Mantenimiento ASG y GPUs
B4: Fullstack Senior (Backend) | C4: 7100000 | D4: =C4*12 -> 85200000 | F4: Spring Boot + Integraciones
B5: Fullstack + IA (Python) | C5: 12300000 | D5: =C5*12 -> 147600000 | F5: ML + Backend
B6: Especialista de Viajes | C6: 2600000 | D6: =C6*12 -> 31200000 | F6: Alianzas GDS y soporte operacional
B7: Home Office (Auxilios) | C7: =95000*5 -> 475000 | D7: =C7*12 -> 5700000 | E7: Movistar | F7: Internet
C8: =180000*5 -> 900000 | D8: =C8*12 -> 10800000 | E8: Enel | F8: Luz
A9: Operación | B9: Infraestructura Cloud AWS | C9: =Cloud!$C$11 -> 2572542 | D9: =C9*12 -> 30870504 | E9: AWS Pricing Calculator | F9: Detalle en hoja Cloud
B10: Marketing Digital | C10: 3370000 | D10: =C10*12 -> 40440000 | E10: Marketing CPE | F10: Campañas de adquisición y retención
B11: APIs Externas | C11: =Transaccional!$D$6 -> 29354850 | D11: =C11*12 -> 352258200 | E11: Transaccional | F11: Amadeus + Google Maps + Twilio
A12: TOTAL OPEX | C12: =SUM(C2:C11) -> 73272392 | D12: =SUM(D2:D11) -> 879268704

Sheet Inputs
A1: Inputs - Variables Editables del Modelo Financiero
A3: Variable | B3: Valor | C3: Unidad | D3: Supuesto / Fuente
A5: Parámetros de Usuarios
A6: Base usuarios free mes 1 | B6: 180 | C6: usuarios | D6: Usuarios free en lanzamiento (beta cerrada)
A7: Nuevos usuarios adquiridos mes 1 | B7: 100 | C7: usuarios | D7: Meta acquisición mes 1 (SEO + pauta inicial)
A8: Crecimiento nuevos usuarios (/mes) | B8: 0.15 | C8: %/mes | D8: Benchmark SaaS early-stage: 10-25%/mes
A9: Conversión inicial free a premium | B9: 0.1 | C9: % | D9: De nuevos usuarios: % inician como premium directamente
A10: Conversión ongoing (free a prem/mes) | B10: 0.02 | C10: %/mes | D10: Usuarios free existentes que convierten cada mes
A11: Churn free (%/mes) | B11: 0.25 | C11: %/mes | D11: Alto: usuarios sin compromiso; referencia apps similares
A12: Churn premium (%/mes) | B12: 0.08 | C12: %/mes | D12: Aproximadamente 12.5 meses promedio suscripción (benchmark SaaS B2C)
A13: Churn B2B (%/mes) | B13: 0.03 | C13: %/mes | D13: Aproximadamente 33 meses LTV; contratos anuales reducen churn real
A14: Reservas/usuario free/mes | B14: 0.5 | C14: reservas | D14: Estimado: 1 reserva cada 2 meses por usuario free
A15: Reservas/usuario premium/mes | B15: 2 | C15: reservas | D15: Premium: mayor uso e intención de compra
A17: Parámetros de Inteligencia Artificial
A18: Requests IA / user free / mes | B18: 20 | C18: req/user | D18: Búsquedas IA, sugerencias destino, chatbot básico
A19: Requests IA / user premium / mes | B19: 200 | C19: req/user | D19: Planificación avanzada, RAG, itinerarios, CO2 predicción
A20: Costo marginal por request (COP) | B20: 2 | C20: COP/req | D20: vLLM self-hosted en EC2; estimado vs throughput GPU T4
A21: Capacidad GPU 1 bloque (req/mes) | B21: 1500000 | C21: requests | D21: 1× g4dn.xlarge T4 a promedio 50K req/día
A22: Costo GPU adicional (COP/bloque) | B22: 1260000 | C22: COP/mes | D22: 1× g4dn.xlarge 1-yr reserved aproximadamente $300/mes = COP 1.26M
A24: Pricing y Monetización
A25: Precio suscripción premium | B25: 29900 | C25: COP/mes | D25: Aproximadamente $7.1 USD/mes; comparable con Duolingo Plus / Spotify Colombia
A26: Ticket promedio por transacción | B26: =Supuestos!$A$19 -> 500000 | C26: COP | D26: Viaje nacional promedio (aéreo + hotel 2 noches)
A27: Tasa de comisión | B27: 0.1 | C27: % | D27: 10% sobre valor de reserva; estándar OTA mercado Colombia
A28: Costo Wompi / transacción (COP) | B28: =(B26*0.0265)+700 -> 13950 | C28: COP/trans | D28: 2.65% * $500K + $700; neto costo procesamiento
A29: Revenue B2B / cliente / mes | B29: =Supuestos!$A$19 -> 500000 | C29: COP | D29: Publicidad posicionada + herramientas analítica para operadores
A30: Mes inicio clientes B2B | B30: 3 | C30: mes | D30: Primeros clientes B2B desde mes 3 (post-tracción inicial)
A31: Clientes B2B al inicio | B31: 2 | C31: clientes | D31: 2 clientes piloto en mes de lanzamiento B2B
A32: Nuevos clientes B2B / mes | B32: 1 | C32: clientes | D32: Crecimiento conservador: 1 cliente nuevo/mes (ventas outbound)
A34: Costos de Adquisición (CAC)
A35: CAC usuario free (COP) | B35: 15000 | C35: COP | D35: Aproximadamente $3.6 USD; pauta digital (Meta/Google) Colombia 2025
A36: CAC usuario premium (COP) | B36: 45000 | C36: COP | D36: CAC total (free + conversión); incluye incentivo upgrade
A37: CAC cliente B2B (COP) | B37: =Supuestos!$A$19 -> 500000 | C37: COP | D37: Costo ventas outbound + demos + onboarding B2B
A39: OPEX Mensual (Estructura de Costos)
A40: OPEX Talento / mes | B40: =SUM(OPEX!C2:'OPEX'!C8) -> 37975000 | C40: COP/mes | D40: 5 profesionales; fuente: Payscale Colombia 2025
A41: OPEX Cloud AWS / mes | B41: 5472542 | C41: COP/mes | D41: RDS corregido a $500 USD/mes; EC2 GPU a $300 USD/mes
A42: OPEX Marketing base / mes | B42: 3370000 | C42: COP/mes | D42: Campañas retención; excluye CAC (se calcula aparte)
A43: OPEX APIs fijas base / mes | B43: =10000000 -> 10000000 | C43: COP/mes | D43: Mínimo consumo: Google Maps + Amadeus + Twilio fijo
A44: OPEX APIs variable / usuario | B44: =1000 -> 1000 | C44: COP/user | D44: Amadeus+Maps incremental por usuario activo
A46: CAPEX y Amortización
A47: CAPEX total | B47: =CAPEX!$C$8 -> 218087168 | C47: COP | D47: MVP + Legal + UX/UI + Marketing lanzamiento
...

Sheet Unit Economics
A1: Unit Economics - Por Segmento de Usuario
A2: Métrica | B2: Free (B2C) | C2: Premium (B2C) | D2: B2B Operador | E2: Notas
A4: Ingresos por Unidad (Mensual / Usuario)
A5: Comisiones por reservas (COP/mes) | B5: =Inputs!$B$14*Inputs!$B$26*Inputs!$B$27 -> 25000 | C5: =Inputs!$B$15*Inputs!$B$26*Inputs!$B$27 -> 100000 | D5: 0 | E5: Free: 0.5 res * $500K * 10% | Premium: 2 res * $500K * 10% | B2B: n/a
A6: Suscripción premium (COP/mes) | B6: 0 | C6: =Inputs!$B$25 -> 29900 | D6: 0 | E6: Solo aplica para segmento premium
A7: Publicidad / SaaS B2B (COP/mes) | B7: 0 | C7: 0 | D7: =Inputs!$B$29 -> 500000 | E7: Posicionamiento + herramientas analítica por operador
A8: INGRESO TOTAL / UNIDAD | B8: =SUM(B5:B7) -> 25000 | C8: =SUM(C5:C7) -> 129900 | D8: =SUM(D5:D7) -> 500000 | E8: Ingreso bruto mensual por usuario / cliente
A10: Costos Variables Por Unidad (Mensual)
A11: Costo Wompi / trans. (COP/mes) | B11: =Inputs!$B$14*Inputs!$B$28 -> 6975 | C11: =Inputs!$B$15*Inputs!$B$28 -> 27900 | D11: =0 -> 0 | E11: Wompi: COP 13,950 por transacción; B2B: pago directo entre partes
A12: Costo IA marginal (COP/mes) | B12: =Inputs!$B$18*Inputs!$B$20 -> 40 | C12: =Inputs!$B$19*Inputs!$B$20 -> 400 | D12: =Inputs!$B$19*Inputs!$B$20*2 -> 800 | E12: vLLM on EC2; costo marginal por request en GPU T4
A13: APIs variable (COP/mes) | B13: =Inputs!$B$44 -> 1000 | C13: =Inputs!$B$44 -> 1000 | D13: =Inputs!$B$44*2 -> 2000 | E13: Google Maps + Amadeus incremental por usuario activo
A14: COGS TOTAL / UNIDAD | B14: =SUM(B11:B13) -> 8015 | C14: =SUM(C11:C13) -> 29300 | D14: =SUM(D11:D13) -> 2800 | E14: Suma de costos variables directos por unidad
A16: Rentabilidad por Unidad
A17: Contribución marginal bruta | B17: =B8-B14 -> 16985 | C17: =C8-C14 -> 100600 | D17: =D8-D14 -> 497200 | E17: Ingreso - COGS variable; positivo = cada unidad genera caja
A18: Margen de contribución (%) | B18: =IFERROR((B8-B14)/B8,0) -> 0.6794 | C18: =IFERROR((C8-C14)/C8,0) -> 0.77444188 | D18: =IFERROR((D8-D14)/D8,0) -> 0.9944 | E18: Objetivo mínimo: 60% para cubrir costos fijos
A20: Métricas de Adquisición y Retención
A21: CAC (COP) | B21: =Inputs!$B$35 -> 15000 | C21: =Inputs!$B$36 -> 45000 | D21: =Inputs!$B$37 -> 500000 | E21: Costo de adquisición del cliente; Free: orgánico+digital, Prem: upgrade, B2B: ventas
A22: Churn mensual (%) | B22: =Inputs!$B$11 -> 0.25 | C22: =Inputs!$B$12 -> 0.08 | D22: =Inputs!$B$13 -> 0.03 | E22: Tasa de cancelación mensual por segmento
A23: Vida promedio (meses) | B23: =IFERROR(1/Inputs!$B$11,0) -> 4 | C23: =IFERROR(1/Inputs!$B$12,0) -> 12.5 | D23: =IFERROR(1/Inputs!$B$13,0) -> 33.333333
A24: LTV (COP) | B24: =B17*B23 -> 67940 | C24: =C17*C23 -> 1257500 | D24: =D17*D23 -> 16573333 | E24: Lifetime Value = Contribución * Vida promedio (meses)
A25: LTV / CAC | B25: =IFERROR(B24/B21,0) -> 4.5293333 | C25: =IFERROR(C24/C21,0) -> 27.944444 | D25: =IFERROR(D24/D21,0) -> 33.146667 | E25: Ratio mínimo saludable: 3x. >10x = excelente eficiencia de capital
A26: Payback CAC (meses) | B26: =IFERROR(B21/B17,0) -> 0.88313218 | C26: =IFERROR(C21/C17,0) -> 0.4473161 | D26: =IFERROR(D21/D17,0) -> 1.0056315 | E26: Meses para recuperar CAC con contribución mensual; objetivo <12 meses
A28: Análisis de Viabilidad
A29: ¿Margen positivo por unidad? | B29: =IF(B17>0,"SÍ","No") -> SÍ | C29: =IF(C17>0,"SÍ","No") -> SÍ | D29: =IF(D17>0,"SÍ","No") -> SÍ
A30: ¿LTV/CAC ≥ 3x? | B30: =IF(B25>=3,"SÍ","Revisar") -> SÍ | C30: =IF(C25>=3,"SÍ","Revisar") -> SÍ | D30: =IF(D25>=3,"SÍ","Revisar") -> SÍ
A31: ¿Payback < 12 meses? | B31: =IF(B26<12,"SÍ","Revisar") -> SÍ | C31: =IF(C26<12,"SÍ","Revisar") -> SÍ | D31: =IF(D26<12,"SÍ","Revisar") -> SÍ

Sheet P&G 12 Meses
A1: Estado de Resultados (P&G) Proyectado - 12 Meses
A3: Concepto (COP) | B3: Mes 1 | C3: Mes 2 | D3: Mes 3 | E3: Mes 4 | F3: Mes 5 | G3: Mes 6 | H3: Mes 7 | I3: Mes 8 | J3: Mes 9 | K3: Mes 10 | L3: Mes 11 | M3: Mes 12 | N3: Año 1 Total
A4: Usuarios
A5: Nuevos usuarios adquiridos | B5: =ROUND(Inputs!$B$7*(1+Inputs!$B$8)^0,0) -> 100 | C5: =ROUND(Inputs!$B$7*(1+Inputs!$B$8)^1,0) -> 115 | D5: =ROUND(Inputs!$B$7*(1+Inputs!$B$8)^2,0) -> 132 | E5: =ROUND(Inputs!$B$7*(1+Inputs!$B$8)^3,0) -> 152 | F5: =ROUND(Inputs!$B$7*(1+Inputs!$B$8)^4,0) -> 175 | G5: =ROUND(Inputs!$B$7*(1+Inputs!$B$8)^5,0) -> 201 | H5: =ROUND(Inputs!$B$7*(1+Inputs!$B$8)^6,0) -> 231 | I5: =ROUND(Inputs!$B$7*(1+Inputs!$B$8)^7,0) -> 266 | J5: =ROUND(Inputs!$B$7*(1+Inputs!$B$8)^8,0) -> 306 | K5: =ROUND(Inputs!$B$7*(1+Inputs!$B$8)^9,0) -> 352 | L5: =ROUND(Inputs!$B$7*(1+Inputs!$B$8)^10,0) -> 405 | M5: =ROUND(Inputs!$B$7*(1+Inputs!$B$8)^11,0) -> 465 | N5: =SUM(B5:M5) -> 2900
A6: Usuarios Free (neto fin de mes) | B6: =ROUND((Inputs!$B$6*(1-Inputs!$B$9))+B5*(1-Inputs!$B$9),0) -> 252 | C6: =ROUND(B6*(1-Inputs!$B$11-Inputs!$B$10)+C5*(1-Inputs!$B$9),0) -> 287 | D6: =ROUND(C6*(1-Inputs!$B$11-Inputs!$B$10)+D5*(1-Inputs!$B$9),0) -> 328 | E6: =ROUND(D6*(1-Inputs!$B$11-Inputs!$B$10)+E5*(1-Inputs!$B$9),0) -> 376 | F6: =ROUND(E6*(1-Inputs!$B$11-Inputs!$B$10)+F5*(1-Inputs!$B$9),0) -> 432 | G6: =ROUND(F6*(1-Inputs!$B$11-Inputs!$B$10)+G5*(1-Inputs!$B$9),0) -> 496 | H6: =ROUND(G6*(1-Inputs!$B$11-Inputs!$B$10)+H5*(1-Inputs!$B$9),0) -> 570 | I6: =ROUND(H6*(1-Inputs!$B$11-Inputs!$B$10)+I5*(1-Inputs!$B$9),0) -> 656 | J6: =ROUND(I6*(1-Inputs!$B$11-Inputs!$B$10)+J5*(1-Inputs!$B$9),0) -> 754 | ... M6: =ROUND(L6*(1-Inputs!$B$11-Inputs!$B$10)+M5*(1-Inputs!$B$9),0) -> 1146 | N6: =SUM(B6:M6) -> 7161
A7: Usuarios Premium (neto fin de mes) | B7: =ROUND((Inputs!$B$6*Inputs!$B$9)+B5*Inputs!$B$9,0) -> 28 | C7: =ROUND(B7*(1-Inputs!$B$12)+B6*Inputs!$B$10+C5*Inputs!$B$9,0) -> 42 | D7: =ROUND(C7*(1-Inputs!$B$12)+C6*Inputs!$B$10+D5*Inputs!$B$9,0) -> 58 | E7: =ROUND(D7*(1-Inputs!$B$12)+D6*Inputs!$B$10+E5*Inputs!$B$9,0) -> 75 | F7: =ROUND(E7*(1-Inputs!$B$12)+E6*Inputs!$B$10+F5*Inputs!$B$9,0) -> 94 | G7: =ROUND(F7*(1-Inputs!$B$12)+F6*Inputs!$B$10+G5*Inputs!$B$9,0) -> 115 | H7: =ROUND(G7*(1-Inputs!$B$12)+G6*Inputs!$B$10+H5*Inputs!$B$9,0) -> 139 | I7: =ROUND(H7*(1-Inputs!$B$12)+H6*Inputs!$B$10+I5*Inputs!$B$9,0) -> 166 | J7: =ROUND(I7*(1-Inputs!$B$12)+I6*Inputs!$B$10+J5*Inputs!$B$9,0) -> 196 | ... M7: =ROUND(L7*(1-Inputs!$B$12)+L6*Inputs!$B$10+M5*Inputs!$B$9,0) -> 315 | N7: =SUM(B7:M7) -> 1729
A8: Clientes B2B (neto) | B8: =IF(1>=Inputs!$B$30,Inputs!$B$31,0) -> 0 | C8: =IF(2>=Inputs!$B$30,ROUND(B8*(1-Inputs!$B$13)+IF(2=Inputs!$B$30,Inputs!$B$31,Inputs!$B$32),0),0) -> 0 | D8: =IF(3>=Inputs!$B$30,ROUND(C8*(1-Inputs!$B$13)+IF(3=Inputs!$B$30,Inputs!$B$31,Inputs!$B$32),0),0) -> 2 | E8: =IF(4>=Inputs!$B$30,ROUND(D8*(1-Inputs!$B$13)+IF(4=Inputs!$B$30,Inputs!$B$31,Inputs!$B$32),0),0) -> 3 | F8: =IF(5>=Inputs!$B$30,ROUND(E8*(1-Inputs!$B$13)+IF(5=Inputs!$B$30,Inputs!$B$31,Inputs!$B$32),0),0) -> 4 | G8: =IF(6>=Inputs!$B$30,ROUND(F8*(1-Inputs!$B$13)+IF(6=Inputs!$B$30,Inputs!$B$31,Inputs!$B$32),0),0) -> 5 | H8: =IF(7>=Inputs!$B$30,ROUND(G8*(1-Inputs!$B$13)+IF(7=Inputs!$B$30,Inputs!$B$31,Inputs!$B$32),0),0) -> 6 | I8: =IF(8>=Inputs!$B$30,ROUND(H8*(1-Inputs!$B$13)+IF(8=Inputs!$B$30,Inputs!$B$31,Inputs!$B$32),0),0) -> 7 | J8: =IF(9>=Inputs!$B$30,ROUND(I8*(1-Inputs!$B$13)+IF(9=Inputs!$B$30,Inputs!$B$31,Inputs!$B$32),0),0) -> 8 | K8: =IF(10>=Inputs!$B$30,ROUND(J8*(1-Inputs!$B$13)+IF(10=Inputs!$B$30,Inputs!$B$31,Inputs!$B$32),0),0) -> 9 | L8: =IF(11>=Inputs!$B$30,ROUND(K8*(1-Inputs!$B$13)+IF(11=Inputs!$B$30,Inputs!$B$31,Inputs!$B$32),0),0) -> 10 | M8: =IF(12>=Inputs!$B$30,ROUND(L8*(1-Inputs!$B$13)+IF(12=Inputs!$B$30,Inputs!$B$31,Inputs!$B$32),0),0) -> 11 | N8: =SUM(B8:M8) -> 65
A9: Nuevos clientes B2B | B9: =IF(1>=Inputs!$B$30,Inputs!$B$31,0) -> 0 | C9: =IF(2=Inputs!$B$30,Inputs!$B$31,IF(2>Inputs!$B$30,Inputs!$B$32,0)) -> 0 | D9: =IF(3=Inputs!$B$30,Inputs!$B$31,IF(3>Inputs!$B$30,Inputs!$B$32,0)) -> 2 | E9: =IF(4=Inputs!$B$30,Inputs!$B$31,IF(4>Inputs!$B$30,Inputs!$B$32,0)) -> 1 | F9: =IF(5=Inputs!$B$30,Inputs!$B$31,IF(5>Inputs!$B$30,Inputs!$B$32,0)) -> 1 | G9: =IF(6=Inputs!$B$30,Inputs!$B$31,IF(6>Inputs!$B$30,Inputs!$B$32,0)) -> 1 | H9: =IF(7=Inputs!$B$30,Inputs!$B$31,IF(7>Inputs!$B$30,Inputs!$B$32,0)) -> 1 | I9: =IF(8=Inputs!$B$30,Inputs!$B$31,IF(8>Inputs!$B$30,Inputs!$B$32,0)) -> 1 | J9: =IF(9=Inputs!$B$30,Inputs!$B$31,IF(9>Inputs!$B$30,Inputs!$B$32,0)) -> 1 | K9: =IF(10=Inputs!$B$30,Inputs!$B$31,IF(10>Inputs!$B$30,Inputs!$B$32,0)) -> 1 | L9: =IF(11=Inputs!$B$30,Inputs!$B$31,IF(11>Inputs!$B$30,Inputs!$B$32,0)) -> 1 | M9: =IF(12=Inputs!$B$30,Inputs!$B$31,IF(12>Inputs!$B$30,Inputs!$B$32,0)) -> 1 | N9: =SUM(B9:M9) -> 11
A10: Total usuarios activos (Free+Premium) | B10: =B6+B7 -> 280 | C10: =C6+C7 -> 329 | D10: =D6+D7 -> 386 | E10: =E6+E7 -> 451 | F10: =F6+F7 -> 526 | G10: =G6+G7 -> 611 | H10: =H6+H7 -> 709 | I10: =I6+I7 -> 822 | ... M10: =M6+M7 -> 1461 | N10: =SUM(B10:M10) -> 8890
A12: Ingresos
A13: Comisiones reservas (Free) | B13: =B6*Inputs!$B$14*Inputs!$B$26*Inputs!$B$27 -> 6300000 | C13: =C6*Inputs!$B$14*Inputs!$B$26*Inputs!$B$27 -> 7175000 | D13: =D6*Inputs!$B$14*Inputs!$B$26*Inputs!$B$27 -> 8200000 | E13: =E6*Inputs!$B$14*Inputs!$B$26*Inputs!$B$27 -> 9400000 | F13: =F6*Inputs!$B$14*Inputs!$B$26*Inputs!$B$27 -> 10800000 | G13: =G6*Inputs!$B$14*Inputs!$B$26*Inputs!$B$27 -> 12400000 | H13: =H6*Inputs!$B$14*Inputs!$B$26*Inputs!$B$27 -> 14250000 | I13: =I6*Inputs!$B$14*Inputs!$B$26*Inputs!$B$27 -> 16400000 | ... M13: =M6*Inputs!$B$14*Inputs!$B$26*Inputs!$B$27 -> 28650000 | N13: =SUM(B13:M13) -> 179025000
A14: Comisiones reservas (Premium) | B14: =B7*Inputs!$B$15*Inputs!$B$26*Inputs!$B$27 -> 2800000 | C14: =C7*Inputs!$B$15*Inputs!$B$26*Inputs!$B$27 -> 4200000 | D14: =D7*Inputs!$B$15*Inputs!$B$26*Inputs!$B$27 -> 5800000 | E14: =E7*Inputs!$B$15*Inputs!$B$26*Inputs!$B$27 -> 7500000 | F14: =F7*Inputs!$B$15*Inputs!$B$26*Inputs!$B$27 -> 9400000 | G14: =G7*Inputs!$B$15*Inputs!$B$26*Inputs!$B$27 -> 11500000 | H14: =H7*Inputs!$B$15*Inputs!$B$26*Inputs!$B$27 -> 13900000 | I14: =I7*Inputs!$B$15*Inputs!$B$26*Inputs!$B$27 -> 16600000 | ... M14: =M7*Inputs!$B$15*Inputs!$B$26*Inputs!$B$27 -> 31500000 | N14: =SUM(B14:M14) -> 172900000
A15: Suscripciones Premium | B15: =B7*Inputs!$B$25 -> 837200 | C15: =C7*Inputs!$B$25 -> 1255800 | D15: =D7*Inputs!$B$25 -> 1734200 | E15: =E7*Inputs!$B$25 -> 2242500 | F15: =F7*Inputs!$B$25 -> 2810600 | G15: =G7*Inputs!$B$25 -> 3438500 | H15: =H7*Inputs!$B$25 -> 4156100 | I15: =I7*Inputs!$B$25 -> 4963400 | ... M15: =M7*Inputs!$B$25 -> 9418500 | N15: =SUM(B15:M15) -> 51697100
A16: Revenue B2B (publicidad + SaaS) | B16: =B8*Inputs!$B$29 -> 0 | C16: =C8*Inputs!$B$29 -> 0 | D16: =D8*Inputs!$B$29 -> 1000000 | E16: =E8*Inputs!$B$29 -> 1500000 | F16: =F8*Inputs!$B$29 -> 2000000 | G16: =G8*Inputs!$B$29 -> 2500000 | H16: =H8*Inputs!$B$29 -> 3000000 | I16: =I8*Inputs!$B$29 -> 3500000 | ... M16: =M8*Inputs!$B$29 -> 5500000 | N16: =SUM(B16:M16) -> 32500000
A17: TOTAL INGRESOS | B17: =SUM(B13:B16) -> 9937200 | C17: =SUM(C13:C16) -> 12630800 | D17: =SUM(D13:D16) -> 16734200 | E17: =SUM(E13:E16) -> 20642500 | F17: =SUM(F13:F16) -> 25010600 | G17: =SUM(G13:G16) -> 29838500 | H17: =SUM(H13:H16) -> 35306100 | I17: =SUM(I13:I16) -> 41463400 | ... M17: =SUM(M13:M16) -> 75068500 | N17: =SUM(B17:M17) -> 436122100
A19: Costo de Ventas (COGS - Variables)
A20: Costo pasarela Wompi | B20: =(B6*Inputs!$B$14+B7*Inputs!$B$15)*Inputs!$B$28 -> 2538900 | C20: =(C6*Inputs!$B$14+C7*Inputs!$B$15)*Inputs!$B$28 -> 3173625 | D20: =(D6*Inputs!$B$14+D7*Inputs!$B$15)*Inputs!$B$28 -> 3906000 | E20: =(E6*Inputs!$B$14+E7*Inputs!$B$15)*Inputs!$B$28 -> 4715100 | F20: =(F6*Inputs!$B$14+F7*Inputs!$B$15)*Inputs!$B$28 -> 5635800 | G20: =(G6*Inputs!$B$14+G7*Inputs!$B$15)*Inputs!$B$28 -> 6668100 | H20: =(H6*Inputs!$B$14+H7*Inputs!$B$15)*Inputs!$B$28 -> 7853850 | I20: =(I6*Inputs!$B$14+I7*Inputs!$B$15)*Inputs!$B$28 -> 9207000 | ... M20: =(M6*Inputs!$B$14+M7*Inputs!$B$15)*Inputs!$B$28 -> 16781850 | N20: =SUM(B20:M20) -> 98187075
A21: Costo IA marginal (vLLM GPU) | B21: =(B6*Inputs!$B$18+B7*Inputs!$B$19)*Inputs!$B$20 -> 21280 | C21: =(C6*Inputs!$B$18+C7*Inputs!$B$19)*Inputs!$B$20 -> 28280 | D21: =(D6*Inputs!$B$18+D7*Inputs!$B$19)*Inputs!$B$20 -> 36320 | E21: =(E6*Inputs!$B$18+E7*Inputs!$B$19)*Inputs!$B$20 -> 45040 | F21: =(F6*Inputs!$B$18+F7*Inputs!$B$19)*Inputs!$B$20 -> 54880 | G21: =(G6*Inputs!$B$18+G7*Inputs!$B$19)*Inputs!$B$20 -> 65840 | H21: =(H6*Inputs!$B$18+H7*Inputs!$B$19)*Inputs!$B$20 -> 78400 | I21: =(I6*Inputs!$B$18+I7*Inputs!$B$19)*Inputs!$B$20 -> 92640 | ... M21: =(M6*Inputs!$B$18+M7*Inputs!$B$19)*Inputs!$B$20 -> 171840 | N21: =SUM(B21:M21) -> 978040
A22: APIs externas (variable por usuario) | B22: =B10*Inputs!$B$44 -> 280000 | C22: =C10*Inputs!$B$44 -> 329000 | D22: =D10*Inputs!$B$44 -> 386000 | E22: =E10*Inputs!$B$44 -> 451000 | F22: =F10*Inputs!$B$44 -> 526000 | G22: =G10*Inputs!$B$44 -> 611000 | H22: =H10*Inputs!$B$44 -> 709000 | I22: =I10*Inputs!$B$44 -> 822000 | ... N22: =N10*Inputs!$B$44 -> 8890000
A23: TOTAL COGS | B23: =SUM(B20:B22) -> 2840180 | C23: =SUM(C20:C22) -> 3530905 | D23: =SUM(D20:D22) -> 4328320 | E23: =SUM(E20:E22) -> 5211140 | F23: =SUM(F20:F22) -> 6216680 | G23: =SUM(G20:G22) -> 7344940 | H23: =SUM(H20:H22) -> 8641250 | I23: =SUM(I20:I22) -> 10121640 | ... M23: =SUM(M20:M22) -> 18414690 | N23: =SUM(B23:M23) -> 108055115
A24: MARGEN BRUTO
A25: MARGEN BRUTO | B25: =B17-B23 -> 7097020 | C25: =C17-C23 -> 9099895 | D25: =D17-D23 -> 12405880 | E25: =E17-E23 -> 15431360 | F25: =F17-F23 -> 18793920 | G25: =G17-G23 -> 22493560 | H25: =H17-H23 -> 26664850 | I25: =I17-I23 -> 31341760 | ... M25: =M17-M23 -> 56653810 | N25: =SUM(B25:M25) -> 328066985
A26: % Margen Bruto | B26: =IFERROR(B25/B17,0) -> 0.71418709 | C26: =IFERROR(C25/C17,0) -> 0.72045278 | D26: =IFERROR(D25/D17,0) -> 0.74134885 | E26: =IFERROR(E25/E17,0) -> 0.74755286 | F26: =IFERROR(F25/F17,0) -> 0.75143819 | G26: =IFERROR(G25/G17,0) -> 0.75384352 | H26: =IFERROR(H25/H17,0) -> 0.75524768 | I26: =IFERROR(I25/I17,0) -> 0.75588977 | ... N26: =IFERROR(N25/N17,0) -> 0.75223655
A28: Gastos Operativos (OPEX Fijo)
A29: Talento humano | B29: =Inputs!$B$40 -> 37975000 | C29: =Inputs!$B$40 -> 37975000 | D29: =Inputs!$B$40 -> 37975000 | E29: =Inputs!$B$40 -> 37975000 | F29: =Inputs!$B$40 -> 37975000 | G29: =Inputs!$B$40 -> 37975000 | H29: =Inputs!$B$40 -> 37975000 | I29: =Inputs!$B$40 -> 37975000 | ... M29: =Inputs!$B$40 -> 37975000 | N29: =SUM(B29:M29) -> 455700000
A30: Infraestructura Cloud AWS (corregida) | B30: =Inputs!$B$41 -> 5472542 | C30: =Inputs!$B$41 -> 5472542 | D30: =Inputs!$B$41 -> 5472542 | E30: =Inputs!$B$41 -> 5472542 | F30: =Inputs!$B$41 -> 5472542 | G30: =Inputs!$B$41 -> 5472542 | H30: =Inputs!$B$41 -> 5472542 | I30: =Inputs!$B$41 -> 5472542 | ... M30: =Inputs!$B$41 -> 5472542 | N30: =SUM(B30:M30) -> 65670504
A31: Marketing digital (base) | B31: =Inputs!$B$42 -> 3370000 | C31: =Inputs!$B$42 -> 3370000 | D31: =Inputs!$B$42 -> 3370000 | E31: =Inputs!$B$42 -> 3370000 | F31: =Inputs!$B$42 -> 3370000 | G31: =Inputs!$B$42 -> 3370000 | H31: =Inputs!$B$42 -> 3370000 | I31: =Inputs!$B$42 -> 3370000 | ... N31: =Inputs!$B$42 -> 3370000
A32: APIs externas (costo mínimo fijo) | B32: =Inputs!$B$43 -> 10000000 | C32: =Inputs!$B$43 -> 10000000 | D32: =Inputs!$B$43 -> 10000000 | E32: =Inputs!$B$43 -> 10000000 | F32: =Inputs!$B$43 -> 10000000 | G32: =Inputs!$B$43 -> 10000000 | H32: =Inputs!$B$43 -> 10000000 | I32: =Inputs!$B$43 -> 10000000 | ... N32: =Inputs!$B$43 -> 10000000
A33: CAC spend (adquisición) | B33: =B5*(1-Inputs!$B$9)*Inputs!$B$35+B5*Inputs!$B$9*Inputs!$B$36+B9*Inputs!$B$37 -> 1800000 | C33: =C5*(1-Inputs!$B$9)*Inputs!$B$35+C5*Inputs!$B$9*Inputs!$B$36+C9*Inputs!$B$37 -> 2070000 | D33: =D5*(1-Inputs!$B$9)*Inputs!$B$35+D5*Inputs!$B$9*Inputs!$B$36+D9*Inputs!$B$37 -> 3376000 | E33: =E5*(1-Inputs!$B$9)*Inputs!$B$35+E5*Inputs!$B$9*Inputs!$B$36+E9*Inputs!$B$37 -> 3236000 | F33: =F5*(1-Inputs!$B$9)*Inputs!$B$35+F5*Inputs!$B$9*Inputs!$B$36+F9*Inputs!$B$37 -> 3650000 | G33: =G5*(1-Inputs!$B$9)*Inputs!$B$35+G5*Inputs!$B$9*Inputs!$B$36+G9*Inputs!$B$37 -> 4118000 | H33: =H5*(1-Inputs!$B$9)*Inputs!$B$35+H5*Inputs!$B$9*Inputs!$B$36+H9*Inputs!$B$37 -> 4658000 | I33: =I5*(1-Inputs!$B$9)*Inputs!$B$35+I5*Inputs!$B$9*Inputs!$B$36+I9*Inputs!$B$37 -> 5288000 | ... M33: =M5*(1-Inputs!$B$9)*Inputs!$B$35+M5*Inputs!$B$9*Inputs!$B$36+M9*Inputs!$B$37 -> 8870000 | N33: =SUM(B33:M33) -> 57700000
A34: TOTAL OPEX | B34: =SUM(B29:B33) -> 58617542 | C34: =SUM(C29:C33) -> 58887542 | D34: =SUM(D29:D33) -> 60193542 | E34: =SUM(E29:E33) -> 60053542 | F34: =SUM(F29:F33) -> 60467542 | G34: =SUM(G29:G33) -> 60935542 | H34: =SUM(H29:H33) -> 61475542 | I34: =SUM(I29:I33) -> 62105542 | ... M34: =SUM(M29:M33) -> 65687542 | N34: =SUM(B34:M34) -> 739510504
A35: Rentabilidad
A36: EBITDA (Utilidad Operativa Bruta) | B36: =B25-B34 -> -51520522 | C36: =C25-C34 -> -49787647 | D36: =D25-D34 -> -47787662 | E36: =E25-E34 -> -44622182 | F36: =F25-F34 -> -41673622 | G36: =G25-G34 -> -38441982 | H36: =H25-H34 -> -34810692 | I36: =I25-I34 -> -30763782 | ... M36: =M25-M34 -> -9033732 | N36: =SUM(B36:M36) -> -411443519
A37: % EBITDA sobre ingresos | B37: =IFERROR(B36/B17,0) -> -5.1846116 | C37: =IFERROR(C36/C17,0) -> -3.9417651 | D37: =IFERROR(D36/D17,0) -> -2.8556885 | E37: =IFERROR(E36/E17,0) -> -2.1616656 | F37: =IFERROR(F36/F17,0) -> -1.6662384 | G37: =IFERROR(G36/G17,0) -> -1.2883349 | H37: =IFERROR(H36/H17,0) -> -0.9859682 | I37: =IFERROR(I36/I17,0) -> -0.7419503 | ... N37: =IFERROR(N36/N17,0) -> -0.9434136
A38: Amortización CAPEX | B38: =Inputs!$B$47/Inputs!$B$48 -> 6057976.9 | C38: =Inputs!$B$47/Inputs!$B$48 -> 6057976.9 | D38: =Inputs!$B$47/Inputs!$B$48 -> 6057976.9 | E38: =Inputs!$B$47/Inputs!$B$48 -> 6057976.9 | F38: =Inputs!$B$47/Inputs!$B$48 -> 6057976.9 | G38: =Inputs!$B$47/Inputs!$B$48 -> 6057976.9 | H38: =Inputs!$B$47/Inputs!$B$48 -> 6057976.9 | I38: =Inputs!$B$47/Inputs!$B$48 -> 6057976.9 | ... N38: =Inputs!$B$47/Inputs!$B$48 -> 6057976.9
A39: EBIT (Utilidad Operativa Neta) | B39: =B36-B38 -> -57578499 | C39: =C36-C38 -> -55845624 | D39: =D36-D38 -> -53845639 | E39: =E36-E38 -> -50680159 | F39: =F36-F38 -> -47731599 | G39: =G36-G38 -> -44499959 | H39: =H36-H38 -> -40868669 | I39: =I36-I38 -> -36821759 | ... M39: =M36-M38 -> -15091709 | N39: =SUM(B39:M39) -> -4.8413924e+08
A40: Impuesto de renta (33%) | B40: =IF(B39>0,B39*Inputs!$B$53,0) -> 0 | C40: =IF(C39>0,C39*Inputs!$B$53,0) -> 0 | D40: =IF(D39>0,D39*Inputs!$B$53,0) -> 0 | E40: =IF(E39>0,E39*Inputs!$B$53,0) -> 0 | F40: =IF(F39>0,F39*Inputs!$B$53,0) -> 0 | G40: =IF(G39>0,G39*Inputs!$B$53,0) -> 0 | H40: =IF(H39>0,H39*Inputs!$B$53,0) -> 0 | I40: =IF(I39>0,I39*Inputs!$B$53,0) -> 0 | ... M40: =IF(M39>0,M39*Inputs!$B$53,0) -> 0 | N40: =SUM(B40:M40) -> 0
A41: UTILIDAD NETA | B41: =B39-B40 -> -57578499 | C41: =C39-C40 -> -55845624 | D41: =D39-D40 -> -53845639 | E41: =E39-E40 -> -50680159 | F41: =F39-F40 -> -47731599 | G41: =G39-G40 -> -44499959 | H41: =H39-H40 -> -40868669 | I41: =I39-I40 -> -36821759 | ... M41: =M39-M40 -> -15091709 | N41: =SUM(B41:M41) -> -4.8413924e+08

Sheet Cash Flow
A1: Flujo de Caja - 12 Meses
A3: Concepto (COP) | B3: Mes 1 | C3: Mes 2 | D3: Mes 3 | E3: Mes 4 | F3: Mes 5 | G3: Mes 6 | H3: Mes 7 | I3: Mes 8 | J3: Mes 9 | K3: Mes 10 | L3: Mes 11 | M3: Mes 12 | N3: Año 1 Total
A4: Actividades Operativas
A5: EBITDA (de PyG) | B5: ='P&G 12 Meses'!B36 -> -51520522 | C5: ='P&G 12 Meses'!C36 -> -49787647 | D5: ='P&G 12 Meses'!D36 -> -47787662 | E5: ='P&G 12 Meses'!E36 -> -44622182 | F5: ='P&G 12 Meses'!F36 -> -41673622 | G5: ='P&G 12 Meses'!G36 -> -38441982 | H5: ='P&G 12 Meses'!H36 -> -34810692 | I5: ='P&G 12 Meses'!I36 -> -30763782 | ... M5: ='P&G 12 Meses'!M36 -> -9033732 | N5: =SUM(B5:M5) -> -411443519
A6: Cambio capital de trabajo (AR lag 5%) | B6: =-'P&G 12 Meses'!B17*0.05 -> -496860 | C6: =-('P&G 12 Meses'!C17 - 'P&G 12 Meses'!B17)*0.05 -> -134680 | D6: =-('P&G 12 Meses'!D17 - 'P&G 12 Meses'!C17)*0.05 -> -205170 | E6: =-('P&G 12 Meses'!E17 - 'P&G 12 Meses'!D17)*0.05 -> -195415 | F6: =-('P&G 12 Meses'!F17 - 'P&G 12 Meses'!E17)*0.05 -> -218405 | G6: =-('P&G 12 Meses'!G17 - 'P&G 12 Meses'!F17)*0.05 -> -241395 | H6: =-('P&G 12 Meses'!H17 - 'P&G 12 Meses'!G17)*0.05 -> -273380 | I6: =-('P&G 12 Meses'!I17 - 'P&G 12 Meses'!H17)*0.05 -> -307865 | J6: =-('P&G 12 Meses'!J17 - 'P&G 12 Meses'!I17)*0.05 -> -342350 | ... M6: =-('P&G 12 Meses'!M17 - 'P&G 12 Meses'!L17)*0.05 -> -503525 | N6: =SUM(B6:M6) -> -3753425
A7: Impuestos pagados | B7: =-'P&G 12 Meses'!C40 -> 0 | C7: =-'P&G 12 Meses'!D40 -> 0 | D7: =-'P&G 12 Meses'!E40 -> 0 | E7: =-'P&G 12 Meses'!F40 -> 0 | F7: =-'P&G 12 Meses'!G40 -> 0 | G7: =-'P&G 12 Meses'!H40 -> 0 | H7: =-'P&G 12 Meses'!I40 -> 0 | I7: =-'P&G 12 Meses'!J40 -> 0 | ... M7: =-'P&G 12 Meses'!N40 -> 0 | N7: =SUM(B7:M7) -> 0
A8: FLUJO CAJA OPERATIVO | B8: =B5+B6+B7 -> -52017382 | C8: =C5+C6+C7 -> -49922327 | D8: =D5+D6+D7 -> -47992832 | E8: =E5+E6+E7 -> -44817597 | F8: =F5+F6+F7 -> -41892027 | G8: =G5+G6+G7 -> -38683377 | H8: =H5+H6+H7 -> -35084072 | I8: =I5+I6+I7 -> -31071647 | ... M8: =M5+M6+M7 -> -9537257 | N8: =SUM(B8:M8) -> -415196944
A10: Actividades de Inversión (CAPEX)
A11: CAPEX inicial (desembolso mes 0/1) | B11: =-Inputs!$B$47 -> -218087168 | C11: =0 -> 0 | D11: =0 -> 0 | E11: =0 -> 0 | F11: =0 -> 0 | G11: =0 -> 0 | H11: =0 -> 0 | I11: =0 -> 0 | J11: =0 -> 0 | ... M11: =0 -> 0 | N11: =SUM(B11:M11) -> -218087168
A12: FLUJO CAJA INVERSIÓN | B12: =B11 -> -218087168 | C12: =C11 -> 0 | D12: =D11 -> 0 | E12: =E11 -> 0 | F12: =F11 -> 0 | G12: =G11 -> 0 | H12: =H11 -> 0 | I12: =I11 -> 0 | ... M12: =M11 -> 0 | N12: =SUM(B12:M12) -> -218087168
A14: Actividades de Financiamiento
A15: Aporte de capital / financiamiento | B15: =0 -> 0 | C15: =0 -> 0 | D15: =0 -> 0 | E15: =0 -> 0 | F15: =0 -> 0 | G15: =0 -> 0 | H15: =0 -> 0 | I15: =0 -> 0 | ... M15: =0 -> 0 | N15: =SUM(B15:M15) -> 0
A16: FLUJO CAJA FINANCIERO | B16: =B15 -> 0 | C16: =C15 -> 0 | D16: =D15 -> 0 | E16: =E15 -> 0 | F16: =F15 -> 0 | G16: =G15 -> 0 | H16: =H15 -> 0 | I16: =I15 -> 0 | ... M16: =M15 -> 0 | N16: =SUM(B16:M16) -> 0
A18: Resumen de Caja
A19: FLUJO NETO DEL PERÍODO | B19: =B8+B12+B16 -> -270104550 | C19: =C8+C12+C16 -> -49922327 | D19: =D8+D12+D16 -> -47992832 | E19: =E8+E12+E16 -> -44817597 | F19: =F8+F12+F16 -> -41892027 | G19: =G8+G12+G16 -> -38683377 | H19: =H8+H12+H16 -> -35084072 | I19: =I8+I12+I16 -> -31071647 | ... M19: =M8+M12+M16 -> -9537257 | N19: =SUM(B19:M19) -> -633284112
A20: SALDO CAJA ACUMULADO | B20: =B19 -> -270104550 | C20: =B20+C19 -> -320026877 | D20: =C20+D19 -> -368019709 | E20: =D20+E19 -> -412837306 | F20: =E20+F19 -> -454729333 | G20: =F20+G19 -> -493412710 | H20: =G20+H19 -> -528496782 | I20: =H20+I19 -> -559568429 | J20: =I20+J19 -> -586212031 | ... M20: =L20+M19 -> -633284112 | N20: =SUM(B20:M20) -> -5858233247
A21: Saldo mínimo requerido (buffer operativo) | B21: =Inputs!$B$40*2 -> 75950000 | C21: =Inputs!$B$40*2 -> 75950000 | D21: =Inputs!$B$40*2 -> 75950000 | E21: =Inputs!$B$40*2 -> 75950000 | F21: =Inputs!$B$40*2 -> 75950000 | G21: =Inputs!$B$40*2 -> 75950000 | H21: =Inputs!$B$40*2 -> 75950000 | I21: =Inputs!$B$40*2 -> 75950000 | ... M21: =Inputs!$B$40*2 -> 75950000 | N21: =SUM(B21:M21) -> 911400000

Sheet Sensibilidad
A1: Análisis de Sensibilidad - Variables Críticas
A3: Ingresos Año 1 (COP M) - Precio Premium * Tasa de Conversión
A4: Los valores se calculan como: Usuarios Premium Promedio * 12 meses * Precio + Comisiones estimadas
A5: Precio Prem \ Conv Rate | B5: Conv 5.0% | C5: Conv 7.5% | D5: Conv 10.0% | E5: Conv 15.0% | F5: Conv 20.0% | G5: Impacto en margen
A6: COP 15,000 | B6: 228 | C6: 250.62 | D6: 276 | E6: 322.92 | F6: 372 | G6: Precio insostenible; no cubre COGS premium
A7: COP 22,000 | B7: 236.4 | C7: 263.136 | D7: 292.8 | E7: 348.036 | F7: 405.6 | G7: Margen ajustado; viable solo con churn <6%
A8: COP 29,900 | B8: 245.88 | C8: 277.2612 | D8: 311.76 | E8: 376.3812 | F8: 443.52 | G8: Precio base recomendado; margen aproximadamente 71%
A9: COP 39,000 | B9: 256.8 | C9: 293.532 | D9: 333.6 | E9: 409.032 | F9: 487.2 | G9: Alta rentabilidad; riesgo de menor conversión
A10: COP 49,000 | B10: 268.8 | C10: 311.412 | D10: 357.6 | E10: 444.912 | F10: 535.2 | G10: Precio premium; requiere validación WTP Colombia
A12: EBITDA Año 1 (COP M) - Churn Premium * Tasa Crecimiento Usuarios
A13: Crec. \ Churn Prem | B13: Churn 4% | C13: Churn 6% | D13: Churn 8% | E13: Churn 12% | F13: Churn 16% | G13: Nota
A14: Crecimiento 5%/mes | B14: -644.34158 | C14: -645.34496 | D14: -646.34834 | E14: -647.35172 | F14: -648.3551 | G14: Crecimiento lento; déficit alto año 1
A15: Crecimiento 10%/mes | B15: -624.87266 | C15: -626.87942 | D15: -627.8828 | E15: -630.89294 | F15: -632.8997 | G15: Posible; requiere eficiencia OPEX
A16: Crecimiento 15%/mes | B16: -605.26992 | C16: -607.27668 | D16: -610.28682 | E16: -613.29696 | F16: -617.31048 | G16: Escenario base; viable con OPEX corregido
A17: Crecimiento 20%/mes | B17: -584.79762 | C17: -588.81114 | D17: -591.82128 | E17: -596.83818 | F17: -600.8517 | G17: Escenario optimista; break-even mes 9-10
A18: Crecimiento 30%/mes | B18: -545.72596 | C18: -550.74286 | D18: -555.75976 | E18: -562.78342 | F18: -569.80708 | G18: Agresivo; requiere mayor inversión en CAC
A20: Sensibilidad al Costo de IA (Impacto en EBITDA Anual)
A21: Costo/req (COP) | B21: Costo IA mensual (500 prem) | C21: % del Revenue | D21: Impacto EBITDA anual | E21: Nota
A22: $0.5 (muy bajo) | B22: COP 50,000 | C22: 0.006 | D22: COP -0.6M | E22: Óptimo; requiere model distillation
A23: $1 (~Mistral small) | B23: COP 100,000 | C23: 0.012 | D23: COP -1.2M | E23: Excelente; Mistral 7B cuantizado viable
A24: $2 (base, vLLM T4) | B24: COP 200,000 | C24: 0.025 | D24: COP -2.4M | E24: BASE RECOMENDADO - vLLM en T4
A25: $5 (API externa económica) | B25: COP 500,000 | C25: 0.062 | D25: COP -6.0M | E25: Límites por request; usage-based necesario
A26: $10 (GPT-3.5) | B26: COP 1,000,000 | C26: 0.125 | D26: COP -12.0M | E26: Marginal negativo; migrar modelo
A27: $20 (GPT-4o mini) | B27: COP 2,000,000 | C27: 0.25 | D27: COP -24.0M | E27: Insostenible; rate limiting obligatorio
A29: Comparativo: Modelos de Monetización de IA
A30: Modelo | B30: Margen por usuario | C30: Impacto caja | D30: Riesgo técnico | E30: Decisión producto | F30: Nota
A31: Rate Limits (solo) | B31: Alto (costos controlados) | C31: Positivo corto plazo | D31: Bajo | E31: Peor UX; abandono premium | F31: Parcial: solo en free tier
A32: Usage-Based (puro) | B32: Variable; protege margen | C32: Impredecible para usuario | D32: Medio (billing infra) | E32: Fricción en conversión | F32: Solo para B2B heavy-use
A33: Suscripción fija | B33: Predecible; riesgo heavy-users | C33: Estable y planificable | D33: Bajo | E33: Mejor UX; stickiness alta | F33: Mantener para B2C
A34: Híbrido | B34: Alto + protección vs abuso | C34: Estable con techo | D34: Medio | E34: Fair use policy clara | F34: ÓPTIMO: Suscripción + límite soft

Sheet Conclusión
A1: Conclusión GO / NO GO
A3: Pricing & Modelo de Monetización IA | D3: Registro de Riesgos Ocultos
A4: PRECIO PREMIUM RECOMENDADO: COP 29,900/mes (Aproximadamente $7.1 USD). Cubre COGS variable (COP 8,370/user: Wompi COP 27,900 + IA COP 400 + API COP 1,000) con margen bruto del 72%. Comparable con Duolingo Plus en Colombia (Aproximadamente COP 28K). Testar con A/B entre COP 24,900 y COP 34,900. | D4: Nivel | E4: Riesgo | F4: Descripción y Mitigación
A5: MODELO HÍBRIDO IA: Suscripción premium con fair use policy de 500 req/mes. Usuarios que superen el límite reciben alerta de uso y opción de consumo adicional a COP 10/req (bundled). Protege contra heavy-users (top 5% consume 40% del cómputo) sin afectar UX del 95% restante. | D5: Alto | E5: Concentración de costos en Amadeus API | F5: Amadeus puede cambiar precios o términos; 100K búsquedas/mes = COP 10.5M. Mitigation: caché + proveedor alternativo (Duffel, Kiwi.com)
A6: INTERACCIÓN MÁS COSTOSA: Planificador de itinerarios con RAG (búsqueda vectorial + LLM). Consume ~10-15 requests compuestos por sesión (RAG retrieval + múltiples prompts). Optimización: cachear resultados de itinerarios populares (destinos top 10 Colombia), reducción estimada del 40% en requests RAG. | D6: Alto | E6: Churn free muy alto (25%/mes) | F6: Con 4 meses de vida promedio, el CAC free de COP 15K tiene payback ajustado. Validar si los usuarios free generan suficientes comisiones o son pure-cost
A7: B2B: Ampliar revenue por cliente. COP 500K/mes es el mínimo viable. Roadmap: Tier básico COP 500K (posicionamiento) -> Tier Analytics COP 1.5M (dashboards) -> Tier API (COP 3M+). Con 15 clientes B2B mes 12: COP 7.5M/mes -> COP 22.5M potencial con upsell. | D7: Medio | E7: Escalabilidad del modelo IA sin control de costos | F7: Con 10,000 usuarios premium a 200 req/mes = 2M req/mes: necesitar 2 bloques GPU. Costo escala, ingresos deben escalar más rápido
D8: Medio | E8: Dependencia de Google Maps API | F8: 1M queries/mes = COP 8.4M. Alternativa: OSM + Mapbox reduce costo 60-70%
A9: Pricing & Estrategia de Crecimiento | D9: Medio | E9: Regulatorio: registro de agencia de viajes | F9: MinCIT puede exigir RNT como intermediario. Estructura legal debe blindarse (marketplace, no agencia)
A10: PUNTO DE EQUILIBRIO: El break-even por comisiones baja de 2,976 a aproximadamente 1,460 reservas/mes. Incorporando suscripciones (300 premium * COP 29,900 = COP 9M/mes), el break-even se alcanza con aproximadamente 900 reservas/mes. Objetivo realista mes 8-10. | D10: Bajo | E10: Competencia de OTAs globales (Booking, Airbnb) | F10: El diferencial de IA local + red social crea moat defensible en mediano plazo. Priorizar nichos que OTAs ignoran: turismo rural, ecoturismo
A11: RATE LIMITS PARA FREE TIER: Limitar a 20 requests IA/mes en free. Aumentar visibilidad del límite para incentivar upgrade (progress bar de uso en app). Beneficio: reduce abuso y crea urgencia de conversión sin eliminar valor del tier gratuito.
A12: CHURN PREMIUM: El 8%/mes (vida aproximadamente 12.5 meses) es aceptable pero mejorable. Implementar: (1) plan anual con 2 meses gratis (reduce churn a aproximadamente 3%/mes efectivo), (2) puntos de lealtad por reservas, (3) save/cancel flow con oferta de descuento 50% por 1 mes.
A13: REDUCIR DEPENDENCIA DE WOMPI: A escala (>5K reservas/mes), evaluar negociación de tarifa preferencial con Wompi o migración a adquirencia directa (reducción de aproximadamente 0.5% = COP 2,500 por transacción de COP 500K = COP 12.5M/año en ahorro con 5K reservas/mes).
A15: Conclusión
A16: DECISIÓN: GO CONDICIONAL El modelo de negocio es VIABLE con ajustes críticos. La propuesta de valor es diferenciada (IA + red social + planificación) y el mercado colombiano tiene runway (turismo +15-20%/año). Sin embargo, el GO está condicionado a: 1. VALIDAR precio premium COP 29,900 con 50 usuarios beta (encuesta WTP) 2. IMPLEMENTAR caché en Amadeus API (reduce COGS en 40-60%) 3. ASEGURAR financiamiento de COP 380-450M (CAPEX + 6 meses runway) 4. DEFINIR fair use policy de IA antes del lanzamiento público
