Workbook

Sheet Indicadores Financieros
A1: Indicadores (lectura desde PyG 36m y FC)
A3: Métrica | B3: Valor
A4: Margen bruto % (ponderado 36m) | B4: ='P&G 36 Meses'!AL26 -> 0.67536369
A5: Margen neto % (ponderado 36m) | B5: ='P&G 36 Meses'!AL42 -> -0.1730394
A6: EBITDA total 36m | B6: ='P&G 36 Meses'!AL36 -> -51742552
A7: EBITDA Margin 36m | B7: ='P&G 36 Meses'!AL37 -> -0.027987043
A8: VPN proyecto | B8: ='FC Proyecto'!B11 -> -3.2989784e+08
A9: TIR anual equiv. proyecto | B9: ='FC Proyecto'!B13 -> -0.29047502
A10: Margen bruto % Año 1 | B10: =SUM('P&G 36 Meses'!B25:M25)/SUM('P&G 36 Meses'!B17:M17) -> 0.67165325
A11: Margen bruto % Año 2 | B11: =SUM('P&G 36 Meses'!N25:Z25)/SUM('P&G 36 Meses'!N17:Z17) -> 0.69271175
A12: Margen bruto % Año 3 | B12: =SUM('P&G 36 Meses'!AA25:AK25)/SUM('P&G 36 Meses'!AA17:AK17) -> 0.66443656
A13: EBITDA Margin % Año 1 | B13: =SUM('P&G 36 Meses'!B36:M36)/SUM('P&G 36 Meses'!B17:M17) -> -1.2005923
A14: EBITDA Margin % Año 2 | B14: =SUM('P&G 36 Meses'!N36:Z36)/SUM('P&G 36 Meses'!N17:Z17) -> -0.012686037
A15: EBITDA Margin % Año 3 | B15: =SUM('P&G 36 Meses'!AA36:AK36)/SUM('P&G 36 Meses'!AA17:AK17) -> 0.2210918
A16: Margen neto % Año 1 | B16: =SUM('P&G 36 Meses'!B41:M41)/SUM('P&G 36 Meses'!B17:M17) -> -1.5379813
A17: Margen neto % Año 2 | B17: =SUM('P&G 36 Meses'!N41:Z41)/SUM('P&G 36 Meses'!N17:Z17) -> -0.13365549
A18: Margen neto % Año 3 | B18: =SUM('P&G 36 Meses'!AA41:AK41)/SUM('P&G 36 Meses'!AA17:AK17) -> 0.1022853

Sheet Supuestos
A1: Categoría | B1: Supuesto | C1: Descripción | D1: Fuente
A2: Técnico | B2: Disponibilidad (SLA) | C2: 99.99% Multi-AZ | D2: AWS Well-Architected
B3: Latencia Máxima | C3: 2 segundos | D3: Estándar industria travel
B4: Cumplimiento Legal | C4: Ley 1581 (Protección datos) | D4: Normativa Colombia
B5: Escalabilidad | C5: Miles de usuarios simultáneos | D5: Diseño ASG + Load Balancers
A6: Mercado | B6: TRM | C6: 1 USD = 4.200 COP | D6: Proyección 2025-2026
B7: Adopción Pagos Digitales | C7: Alta en Colombia | D7: Tendencia e-commerce
B8: Crecimiento E-commerce | C8: 15-20% anual | D8: Benchmarks sectoriales
A9: Operacional | B9: Modelo de Trabajo | C9: 100% Remoto (Home Office) | D9: Ahorro 30% vs oficina
B10: Infraestructura IA | C10: vLLM para servir modelos | D10: Optimización de latencia
B11: Arquitectura | C11: Multi-AZ para redundancia | D11: Garantía transacciones críticas
B12: Desarrollo | C12: 6 meses con 3 personas | D12: Estimación Payscale
B13: Periodo Capitalización | C13: Análisis 12 meses | D13: Horizonte inicial
A15: USD | B15: COP
A16: 1 | B16: 4200
A18: Promedio Transacción
A19: 380000

Sheet CAPEX
A1: Componente | B1: Descripción | C1: Costo (COP) | D1: Fuente | E1: Supuesto
A2: Desarrollo MVP | B2: Full-stack (React + Android + Spring Boot) | C2: =(61041889)*3 -> 183125667 | D2: Payscale Colombia | E2: 6 meses de desarrollo con un equipo de 3 personas, incluyendo mantenimiento hasta completar el costo anual.
A3: Legal y Constitución | B3: Registro mercantil | C3: 194000 | D3: Cámara de Comercio Bogotá | E3: Derechos de matrícula de establecimientos, sucursales o agencias según normativa vigente.
B4: RNT | C4: 0 | D4: Ministerio de Comercio, Industria y Turismo | E4: El RNT es completamente gratuito.
B5: Marcas | C5: 1347500 | D5: Superintendencia de Industria y Comercio | E5: Solicitud de registro de marca o lema comercial por una clase, incluyendo modificaciones no sustanciales.
A6: Diseño UI/UX | B6: Identidad visual y prototipado | C6: =26400002/2 -> 13200001 | D6: Payscale Colombia | E6: 6 meses de trabajo en diseño.
A7: Marketing Lanzamiento | B7: Estrategia de adquisición inicial | C7: =3370000*6 -> 20220000 | D7: Marketing CPE | E7: Inversión en pauta durante los primeros 6 meses posteriores al lanzamiento.
A8: TOTAL CAPEX | C8: =SUM(C2:C7) -> 218087168

Sheet Cloud
A1: Servicio AWS | B1: Descripción | C1: Costo Mensual (COP) | D1: Costo Anual (COP) | E1: Fuente | F1: Supuesto
A2: API Gateway | B2: Gestión REST API | C2: =1*Supuestos!$B$16 -> 4200 | D2: =C2*12 -> 50400 | E2: AWS Pricing Calculator | F2: 1 millón de peticiones mensuales
A3: Application Load Balancer | B3: Balanceo de carga en múltiples zonas (Multi-AZ) | C3: =21.1*Supuestos!$B$16 -> 88620 | D3: =C3*12 -> 1063440 | F3: Instancia base + 0.8 LCU bajo modelo de pago por uso
A4: EC2 | B4: Auto Scaling Group para servicios Spring Boot, gestión de reservas, APIs, FastAPI, procesamiento con GPU NVIDIA T4 y predicción de CO2e (RAG) | C4: =12.26*Supuestos!$B$16 -> 51492 | D4: =C4*12 -> 617904 | F4: Reserva a 1 año con mínimo 4 instancias
A5: RDS | B5: Base de datos primaria en configuración Multi-AZ. Instancias adicionales PostgreSQL Multi-AZ. Base de datos para machine learning y vectores (embeddings) | C5: =500*Supuestos!$B$16 -> 2100000 | D5: =C5*12 -> 25200000 | F5: Alta disponibilidad para cargas críticas y almacenamiento de embeddings y metadatos
A6: S3 Buckets | B6: Almacenamiento de media, logs, pesos de modelos y contenido estático de la aplicación | C6: =4.74*Supuestos!$B$16 -> 19908 | D6: =C6*12 -> 238896 | F6: 200 GB de almacenamiento total + transferencia de datos
A7: CloudFront | B7: Red de distribución de contenido (CDN) | C7: =42.5*Supuestos!$B$16 -> 178500 | D7: =C7*12 -> 2142000 | F7: Aproximadamente 500 GB de salida de datos mensual
A8: SNS/SQS | B8: Capa asincrónica para eventos y colas de mensajes | C8: =20.71*Supuestos!$B$16 -> 86982 | D8: =C8*12 -> 1043784 | F8: Hasta 1 millón de mensajes mensuales
A9: CloudWatch | B9: Monitoreo, logs, métricas y alertas | C9: =10*Supuestos!$B$16 -> 42000 | D9: =C9*12 -> 504000 | F9: Incluye retención de logs y dashboards
A10: Lambda | B10: Procesamiento de tickets y archivos PDF | C10: =0.2*Supuestos!$B$16 -> 840 | D10: =C10*12 -> 10080 | F10: 2 millones de ejecuciones mensuales
A11: TOTAL CLOUD | C11: =SUM(C2:C10) -> 2572542 | D11: =SUM(D2:D10) -> 30870504

Sheet AI
A1: Modelo / Servicio | B1: Tipo de Cobro | C1: Costo Mensual (COP) | D1: Costo Anual (COP) | E1: Escenario de Uso | F1: Supuesto
A2: vLLM | B2: Inferencia Local | C2: 0 | D2: 0 | E2: 24/7 Disponible | F2: Licencia abierta; costo absorbido en EC2 AI
A3: Optimización de Modelos | B3: Fine-tuning Interno | C3: 0 | D3: 0 | E3: Equipo MLOps | F3: Ejecutado por personal interno
A4: TOTAL IA | C4: =SUM(C2:C3) -> 0 | D4: =SUM(D2:D3) -> 0

Sheet Transaccional
A1: Concepto | B1: Tipo de Cobro | C1: Volumen Mensual Estimado | D1: Costo Mensual (COP) | E1: Fuente | F1: Supuesto
A2: Pasarela Wompi | B2: Comisión + Tarifa | C2: 500 transacciones | D2: =(((Supuestos!$A$19*0.0265)+700)*1.19)*ROUND(500*0.35,0) -> 2242852.5 | E2: Wompi | F2: Por cada transacción procesada
A3: Google Maps API | B3: Por Request | C3: 1,000,000 queries | D3: =ROUND(0.12*2013*Supuestos!$B$16,0) -> 1014552 | E3: Maps Platform | F3: Autocompletado y rutas
A4: Amadeus API | B4: Por Request | C4: 100,000 búsquedas | D4: =ROUND(0.1*(0.025*100000)*Supuestos!$B$16,0) -> 1050000 | E4: Amadeus for Developers | F4: Consultas de vuelos y hoteles
A5: Twilio SMS/WhatsApp | B5: Por Mensaje | C5: 100,000 mensajes | D5: =ROUND(0.15*(0.005*100000)*Supuestos!$B$16,0) -> 315000 | E5: Twilio | F5: Notificaciones de confirmación
A6: TOTAL TRANSACCIONAL | D6: =SUM(D2:D5) -> 4622404.5

Sheet OPEX
A1: Categoría | B1: Subcomponente | C1: Costo Mensual (COP) | D1: Costo Anual (COP) | E1: Fuente | F1: Supuesto
A2: Talento | B2: CTO / Líder Técnico | C2: 8000000 | D2: =C2*12 -> 96000000 | E2: Payscale Colombia | F2: Arquitecto AWS + DevOps Senior
B3: MLOps / DevOps | C3: 3600000 | D3: =C3*12 -> 43200000 | F3: Mantenimiento ASG y GPUs
B4: Fullstack Senior (Backend) | C4: 5500000 | D4: =C4*12 -> 66000000 | F4: Spring Boot + Integraciones
B5: Fullstack + IA (Python) | C5: 3000000 | D5: =C5*12 -> 36000000 | F5: ML + Backend
B6: Especialista de Viajes | C6: 1200000 | D6: =C6*12 -> 14400000 | F6: Alianzas GDS y soporte operacional
B7: Home Office (Auxilios) | C7: =95000*5 -> 475000 | D7: =C7*12 -> 5700000 | E7: Movistar | F7: Internet
C8: =180000*5 -> 900000 | D8: =C8*12 -> 10800000 | E8: Enel | F8: Luz
A9: Operación | B9: Infraestructura Cloud AWS | C9: =Cloud!$C$11 -> 2572542 | D9: =C9*12 -> 30870504 | E9: AWS Pricing Calculator | F9: Detalle en hoja Cloud
B10: Marketing Digital | C10: 3370000 | D10: =C10*12 -> 40440000 | E10: Marketing CPE | F10: Campañas de adquisición y retención
B11: APIs Externas | C11: =Transaccional!$D$6 -> 4622404.5 | D11: =C11*12 -> 55468854 | E11: Transaccional | F11: Amadeus + Google Maps + Twilio
A12: TOTAL OPEX | C12: =SUM(C2:C11) -> 33239946 | D12: =SUM(D2:D11) -> 398879358

Sheet Inputs
A1: Inputs - Variables Editables del Modelo Financiero
A3: Variable | B3: Valor | C3: Unidad | D3: Supuesto / Fuente
A5: Parámetros de Usuarios
A6: Base usuarios free mes 1 | B6: 180 | C6: usuarios | D6: Usuarios free en lanzamiento (beta cerrada)
A7: Nuevos usuarios adquiridos mes 1 | B7: 100 | C7: usuarios | D7: Meta acquisición mes 1 (SEO + pauta inicial)
A8: Crecimiento nuevos usuarios (/mes) | B8: 0.05 | C8: %/mes | D8: Benchmark SaaS early-stage: 10-25%/mes
A9: Conversión inicial free a premium | B9: 0.1 | C9: % | D9: De nuevos usuarios: % inician como premium directamente
A10: Conversión ongoing (free a prem/mes) | B10: 0.02 | C10: %/mes | D10: Usuarios free existentes que convierten cada mes
A11: Churn free (%/mes) | B11: 0.12 | C11: %/mes | D11: Alto: usuarios sin compromiso; referencia apps similares
A12: Churn premium (%/mes) | B12: 0.07 | C12: %/mes | D12: Aproximadamente 12.5 meses promedio suscripción (benchmark SaaS B2C)
A13: Churn B2B (%/mes) | B13: 0.03 | C13: %/mes | D13: Aproximadamente 33 meses LTV; contratos anuales reducen churn real
A14: Reservas/usuario free/mes | B14: 0.5 | C14: reservas | D14: Estimado: 1 reserva cada 2 meses por usuario free
A15: Reservas/usuario premium/mes | B15: 2 | C15: reservas | D15: Premium: mayor uso e intención de compra
A17: Parámetros de Inteligencia Artificial
A18: Requests IA / user free / mes | B18: 20 | C18: req/user | D18: Búsquedas IA, sugerencias destino, chatbot básico
A19: Requests IA / user premium / mes | B19: 200 | C19: req/user | D19: Planificación avanzada, RAG, itinerarios, CO2 predicción
A20: Costo marginal por request (COP) | B20: 2 | C20: COP/req | D20: vLLM self-hosted en EC2; estimado vs throughput GPU T4
A21: Capacidad GPU 1 bloque (req/mes) | B21: 1500000 | C21: requests | D21: 1× g4dn.xlarge T4 a promedio 50K req/día
A22: Costo GPU adicional (COP/bloque) | B22: 30000 | C22: COP/mes | D22: 1× g4dn.xlarge 1-yr reserved aproximadamente $300/mes = COP 1.26M
A24: Pricing y Monetización
A25: Precio suscripción premium | B25: 32900 | C25: COP/mes | D25: Aproximadamente $7.1 USD/mes; comparable con Duolingo Plus / Spotify Colombia
A26: Ticket promedio por transacción | B26: =Supuestos!$A$19 -> 380000 | C26: COP | D26: Viaje nacional promedio (aéreo + hotel 2 noches)
A27: Tasa de comisión | B27: 0.055 | C27: % | D27: 10% sobre valor de reserva; estándar OTA mercado Colombia
A28: Costo Wompi / transacción (COP) | B28: =(B26*0.0265)+700 -> 10770 | C28: COP/trans | D28: 2.65% * $500K + $700; neto costo procesamiento
A29: Revenue B2B / cliente / mes | B29: 700000 | C29: COP | D29: Publicidad posicionada + herramientas analítica para operadores
A30: Mes inicio clientes B2B | B30: 3 | C30: mes | D30: Primeros clientes B2B desde mes 3 (post-tracción inicial)
A31: Clientes B2B al inicio | B31: 2 | C31: clientes | D31: 2 clientes piloto en mes de lanzamiento B2B
A32: Nuevos clientes B2B / mes | B32: 1 | C32: clientes | D32: Crecimiento conservador: 1 cliente nuevo/mes (ventas outbound)
A34: Costos de Adquisición (CAC)
A35: CAC usuario free (COP) | B35: 15000 | C35: COP | D35: Aproximadamente $3.6 USD; pauta digital (Meta/Google) Colombia 2025
A36: CAC usuario premium (COP) | B36: 45000 | C36: COP | D36: CAC total (free + conversión); incluye incentivo upgrade
A37: CAC cliente B2B (COP) | B37: =Inputs!$B$54 -> 1800000 | C37: COP | D37: Costo ventas outbound + demos + onboarding B2B
A39: OPEX Mensual (Estructura de Costos)
A40: OPEX Talento / mes | B40: =SUM(OPEX!C2:'OPEX'!C8) -> 22675000 | C40: COP/mes | D40: 5 profesionales; fuente: Payscale Colombia 2025
A41: OPEX Cloud AWS / mes | B41: =Cloud!$C$11+Inputs!$B$22 -> 2602542 | C41: COP/mes | D41: RDS corregido a $500 USD/mes; EC2 GPU a $300 USD/mes
A42: OPEX Marketing base / mes | B42: 1900000 | C42: COP/mes | D42: Campañas retención; excluye CAC (se calcula aparte)
A43: OPEX APIs fijas base / mes | B43: 2400000 | C43: COP/mes | D43: Mínimo consumo: Google Maps + Amadeus + Twilio fijo
A44: OPEX APIs variable / usuario | B44: 720 | C44: COP/user | D44: Amadeus+Maps incremental por usuario activo
A46: CAPEX y Amortización
A47: CAPEX total | B47: =CAPEX!$C$8 -> 218087168 | C47: COP | D47: MVP + Legal + UX/UI + Marketing lanzamiento
...

Sheet Unit Economics
A1: Unit Economics - Por Segmento de Usuario
A2: Métrica | B2: Free (B2C) | C2: Premium (B2C) | D2: B2B Operador | E2: Notas
A4: Ingresos por Unidad (Mensual / Usuario)
A5: Comisiones por reservas (COP/mes) | B5: =Inputs!$B$14*Inputs!$B$26*Inputs!$B$27 -> 10450 | C5: =Inputs!$B$15*Inputs!$B$26*Inputs!$B$27 -> 41800 | D5: 0 | E5: Free: 0.5 res * $500K * 10% | Premium: 2 res * $500K * 10% | B2B: n/a
A6: Suscripción premium (COP/mes) | B6: 0 | C6: =Inputs!$B$25 -> 32900 | D6: 0 | E6: Solo aplica para segmento premium
A7: Publicidad / SaaS B2B (COP/mes) | B7: 0 | C7: 0 | D7: =Inputs!$B$29 -> 700000 | E7: Posicionamiento + herramientas analítica por operador
A8: INGRESO TOTAL / UNIDAD | B8: =SUM(B5:B7) -> 10450 | C8: =SUM(C5:C7) -> 74700 | D8: =SUM(D5:D7) -> 700000 | E8: Ingreso bruto mensual por usuario / cliente
A10: Costos Variables Por Unidad (Mensual)
A11: Costo Wompi / trans. (COP/mes) | B11: =Inputs!$B$14*Inputs!$B$28 -> 5385 | C11: =Inputs!$B$15*Inputs!$B$28 -> 21540 | D11: =0 -> 0 | E11: Wompi: COP 13,950 por transacción; B2B: pago directo entre partes
A12: Costo IA marginal (COP/mes) | B12: =Inputs!$B$18*Inputs!$B$20 -> 40 | C12: =Inputs!$B$19*Inputs!$B$20 -> 400 | D12: =Inputs!$B$19*Inputs!$B$20*2 -> 800 | E12: vLLM on EC2; costo marginal por request en GPU T4
A13: APIs variable (COP/mes) | B13: =Inputs!$B$44 -> 720 | C13: =Inputs!$B$44 -> 720 | D13: =Inputs!$B$44*2 -> 1440 | E13: Google Maps + Amadeus incremental por usuario activo
A14: COGS TOTAL / UNIDAD | B14: =SUM(B11:B13) -> 6145 | C14: =SUM(C11:C13) -> 22660 | D14: =SUM(D11:D13) -> 2240 | E14: Suma de costos variables directos por unidad
A16: Rentabilidad por Unidad
A17: Contribución marginal bruta | B17: =B8-B14 -> 4305 | C17: =C8-C14 -> 52040 | D17: =D8-D14 -> 697760 | E17: Ingreso - COGS variable; positivo = cada unidad genera caja
A18: Margen de contribución (%) | B18: =IFERROR((B8-B14)/B8,0) -> 0.41196172 | C18: =IFERROR((C8-C14)/C8,0) -> 0.69665328 | D18: =IFERROR((D8-D14)/D8,0) -> 0.9968 | E18: Objetivo mínimo: 60% para cubrir costos fijos
A20: Métricas de Adquisición y Retención
A21: CAC (COP) | B21: =Inputs!$B$35 -> 15000 | C21: =Inputs!$B$36 -> 45000 | D21: =Inputs!$B$37 -> 1800000 | E21: Costo de adquisición del cliente; Free: orgánico+digital, Prem: upgrade, B2B: ventas
A22: Churn mensual (%) | B22: =Inputs!$B$11 -> 0.12 | C22: =Inputs!$B$12 -> 0.07 | D22: =Inputs!$B$13 -> 0.03 | E22: Tasa de cancelación mensual por segmento
A23: Vida promedio (meses) | B23: =IFERROR(1/Inputs!$B$11,0) -> 8.3333333 | C23: =IFERROR(1/Inputs!$B$12,0) -> 14.285714 | D23: =IFERROR(1/Inputs!$B$13,0) -> 33.333333
A24: LTV (COP) | B24: =B17*B23 -> 35875 | C24: =C17*C23 -> 743428.57 | D24: =D17*D23 -> 23258667 | E24: Lifetime Value = Contribución * Vida promedio (meses)
A25: LTV / CAC | B25: =IFERROR(B24/B21,0) -> 2.3916667 | C25: =IFERROR(C24/C21,0) -> 16.520635 | D25: =IFERROR(D24/D21,0) -> 12.921481 | E25: Ratio mínimo saludable: 3x. >10x = excelente eficiencia de capital
A26: Payback CAC (meses) | B26: =IFERROR(B21/B17,0) -> 3.4843206 | C26: =IFERROR(C21/C17,0) -> 0.86471945 | D26: =IFERROR(D21/D17,0) -> 2.5796836 | E26: Meses para recuperar CAC con contribución mensual; objetivo <12 meses
A28: Análisis de Viabilidad
A29: ¿Margen positivo por unidad? | B29: =IF(B17>0,"SÍ","No") -> SÍ | C29: =IF(C17>0,"SÍ","No") -> SÍ | D29: =IF(D17>0,"SÍ","No") -> SÍ
A30: ¿LTV/CAC ≥ 3x? | B30: =IF(B25>=3,"SÍ","Revisar") -> Revisar | C30: =IF(C25>=3,"SÍ","Revisar") -> SÍ | D30: =IF(D25>=3,"SÍ","Revisar") -> SÍ
A31: ¿Payback < 12 meses? | B31: =IF(B26<12,"SÍ","Revisar") -> SÍ | C31: =IF(C26<12,"SÍ","Revisar") -> SÍ | D31: =IF(D26<12,"SÍ","Revisar") -> SÍ

Sheet P&G 12 Meses
A1: Estado de Resultados (P&G) Proyectado - 12 Meses
A3: Concepto (COP) | B3: Mes 1 | C3: Mes 2 | D3: Mes 3 | E3: Mes 4 | F3: Mes 5 | G3: Mes 6 | H3: Mes 7 | I3: Mes 8 | J3: Mes 9 | K3: Mes 10 | L3: Mes 11 | M3: Mes 12 | N3: Año 1 Total
A4: Usuarios
A5: Nuevos usuarios adquiridos | B5: =ROUND(Inputs!$B$7*(1+Inputs!$B$8)^0,0) -> 100 | C5: =ROUND(Inputs!$B$7*(1+Inputs!$B$8)^1,0) -> 105 | D5: =ROUND(Inputs!$B$7*(1+Inputs!$B$8)^2,0) -> 110 | E5: =ROUND(Inputs!$B$7*(1+Inputs!$B$8)^3,0) -> 116 | F5: =ROUND(Inputs!$B$7*(1+Inputs!$B$8)^4,0) -> 122 | G5: =ROUND(Inputs!$B$7*(1+Inputs!$B$8)^5,0) -> 128 | H5: =ROUND(Inputs!$B$7*(1+Inputs!$B$8)^6,0) -> 134 | I5: =ROUND(Inputs!$B$7*(1+Inputs!$B$8)^7,0) -> 141 | J5: =ROUND(Inputs!$B$7*(1+Inputs!$B$8)^8,0) -> 148 | K5: =ROUND(Inputs!$B$7*(1+Inputs!$B$8)^9,0) -> 155 | L5: =ROUND(Inputs!$B$7*(1+Inputs!$B$8)^10,0) -> 163 | M5: =ROUND(Inputs!$B$7*(1+Inputs!$B$8)^11,0) -> 171 | N5: =SUM(B5:M5) -> 1593
A6: Usuarios Free (neto fin de mes) | B6: =ROUND((Inputs!$B$6*(1-Inputs!$B$9))+B5*(1-Inputs!$B$9),0) -> 252 | C6: =ROUND(B6*(1-Inputs!$B$11-Inputs!$B$10)+C5*(1-Inputs!$B$9),0) -> 311 | D6: =ROUND(C6*(1-Inputs!$B$11-Inputs!$B$10)+D5*(1-Inputs!$B$9),0) -> 366 | E6: =ROUND(D6*(1-Inputs!$B$11-Inputs!$B$10)+E5*(1-Inputs!$B$9),0) -> 419 | F6: =ROUND(E6*(1-Inputs!$B$11-Inputs!$B$10)+F5*(1-Inputs!$B$9),0) -> 470 | G6: =ROUND(F6*(1-Inputs!$B$11-Inputs!$B$10)+G5*(1-Inputs!$B$9),0) -> 519 | H6: =ROUND(G6*(1-Inputs!$B$11-Inputs!$B$10)+H5*(1-Inputs!$B$9),0) -> 567 | I6: =ROUND(H6*(1-Inputs!$B$11-Inputs!$B$10)+I5*(1-Inputs!$B$9),0) -> 615 | J6: =ROUND(I6*(1-Inputs!$B$11-Inputs!$B$10)+J5*(1-Inputs!$B$9),0) -> 662 | ... M6: =ROUND(L6*(1-Inputs!$B$11-Inputs!$B$10)+M5*(1-Inputs!$B$9),0) -> 804 | N6: =SUM(B6:M6) -> 6450
A7: Usuarios Premium (neto fin de mes) | B7: =ROUND((Inputs!$B$6*Inputs!$B$9)+B5*Inputs!$B$9,0) -> 28 | C7: =ROUND(B7*(1-Inputs!$B$12)+B6*Inputs!$B$10+C5*Inputs!$B$9,0) -> 42 | D7: =ROUND(C7*(1-Inputs!$B$12)+C6*Inputs!$B$10+D5*Inputs!$B$9,0) -> 56 | E7: =ROUND(D7*(1-Inputs!$B$12)+D6*Inputs!$B$10+E5*Inputs!$B$9,0) -> 71 | F7: =ROUND(E7*(1-Inputs!$B$12)+E6*Inputs!$B$10+F5*Inputs!$B$9,0) -> 87 | G7: =ROUND(F7*(1-Inputs!$B$12)+F6*Inputs!$B$10+G5*Inputs!$B$9,0) -> 103 | H7: =ROUND(G7*(1-Inputs!$B$12)+G6*Inputs!$B$10+H5*Inputs!$B$9,0) -> 120 | I7: =ROUND(H7*(1-Inputs!$B$12)+H6*Inputs!$B$10+I5*Inputs!$B$9,0) -> 137 | J7: =ROUND(I7*(1-Inputs!$B$12)+I6*Inputs!$B$10+J5*Inputs!$B$9,0) -> 155 | ... M7: =ROUND(L7*(1-Inputs!$B$12)+L6*Inputs!$B$10+M5*Inputs!$B$9,0) -> 210 | N7: =SUM(B7:M7) -> 1373
A8: Clientes B2B (neto) | B8: =IF(1>=Inputs!$B$30,Inputs!$B$31,0) -> 0 | C8: =IF(2>=Inputs!$B$30,ROUND(B8*(1-Inputs!$B$13)+IF(2=Inputs!$B$30,Inputs!$B$31,Inputs!$B$32),0),0) -> 0 | D8: =IF(3>=Inputs!$B$30,ROUND(C8*(1-Inputs!$B$13)+IF(3=Inputs!$B$30,Inputs!$B$31,Inputs!$B$32),0),0) -> 2 | E8: =IF(4>=Inputs!$B$30,ROUND(D8*(1-Inputs!$B$13)+IF(4=Inputs!$B$30,Inputs!$B$31,Inputs!$B$32),0),0) -> 3 | F8: =IF(5>=Inputs!$B$30,ROUND(E8*(1-Inputs!$B$13)+IF(5=Inputs!$B$30,Inputs!$B$31,Inputs!$B$32),0),0) -> 4 | G8: =IF(6>=Inputs!$B$30,ROUND(F8*(1-Inputs!$B$13)+IF(6=Inputs!$B$30,Inputs!$B$31,Inputs!$B$32),0),0) -> 5 | H8: =IF(7>=Inputs!$B$30,ROUND(G8*(1-Inputs!$B$13)+IF(7=Inputs!$B$30,Inputs!$B$31,Inputs!$B$32),0),0) -> 6 | I8: =IF(8>=Inputs!$B$30,ROUND(H8*(1-Inputs!$B$13)+IF(8=Inputs!$B$30,Inputs!$B$31,Inputs!$B$32),0),0) -> 7 | J8: =IF(9>=Inputs!$B$30,ROUND(I8*(1-Inputs!$B$13)+IF(9=Inputs!$B$30,Inputs!$B$31,Inputs!$B$32),0),0) -> 8 | K8: =IF(10>=Inputs!$B$30,ROUND(J8*(1-Inputs!$B$13)+IF(10=Inputs!$B$30,Inputs!$B$31,Inputs!$B$32),0),0) -> 9 | L8: =IF(11>=Inputs!$B$30,ROUND(K8*(1-Inputs!$B$13)+IF(11=Inputs!$B$30,Inputs!$B$31,Inputs!$B$32),0),0) -> 10 | M8: =IF(12>=Inputs!$B$30,ROUND(L8*(1-Inputs!$B$13)+IF(12=Inputs!$B$30,Inputs!$B$31,Inputs!$B$32),0),0) -> 11 | N8: =SUM(B8:M8) -> 65
A9: Nuevos clientes B2B | B9: =IF(1>=Inputs!$B$30,Inputs!$B$31,0) -> 0 | C9: =IF(2=Inputs!$B$30,Inputs!$B$31,IF(2>Inputs!$B$30,Inputs!$B$32,0)) -> 0 | D9: =IF(3=Inputs!$B$30,Inputs!$B$31,IF(3>Inputs!$B$30,Inputs!$B$32,0)) -> 2 | E9: =IF(4=Inputs!$B$30,Inputs!$B$31,IF(4>Inputs!$B$30,Inputs!$B$32,0)) -> 1 | F9: =IF(5=Inputs!$B$30,Inputs!$B$31,IF(5>Inputs!$B$30,Inputs!$B$32,0)) -> 1 | G9: =IF(6=Inputs!$B$30,Inputs!$B$31,IF(6>Inputs!$B$30,Inputs!$B$32,0)) -> 1 | H9: =IF(7=Inputs!$B$30,Inputs!$B$31,IF(7>Inputs!$B$30,Inputs!$B$32,0)) -> 1 | I9: =IF(8=Inputs!$B$30,Inputs!$B$31,IF(8>Inputs!$B$30,Inputs!$B$32,0)) -> 1 | J9: =IF(9=Inputs!$B$30,Inputs!$B$31,IF(9>Inputs!$B$30,Inputs!$B$32,0)) -> 1 | K9: =IF(10=Inputs!$B$30,Inputs!$B$31,IF(10>Inputs!$B$30,Inputs!$B$32,0)) -> 1 | L9: =IF(11=Inputs!$B$30,Inputs!$B$31,IF(11>Inputs!$B$30,Inputs!$B$32,0)) -> 1 | M9: =IF(12=Inputs!$B$30,Inputs!$B$31,IF(12>Inputs!$B$30,Inputs!$B$32,0)) -> 1 | N9: =SUM(B9:M9) -> 11
A10: Total usuarios activos (Free+Premium) | B10: =B6+B7 -> 280 | C10: =C6+C7 -> 353 | D10: =D6+D7 -> 422 | E10: =E6+E7 -> 490 | F10: =F6+F7 -> 557 | G10: =G6+G7 -> 622 | H10: =H6+H7 -> 687 | I10: =I6+I7 -> 752 | ... M10: =M6+M7 -> 1014 | N10: =SUM(B10:M10) -> 7823
A12: Ingresos
A13: Comisiones reservas (Free) | B13: =B6*Inputs!$B$14*Inputs!$B$26*Inputs!$B$27 -> 2633400 | C13: =C6*Inputs!$B$14*Inputs!$B$26*Inputs!$B$27 -> 3249950 | D13: =D6*Inputs!$B$14*Inputs!$B$26*Inputs!$B$27 -> 3824700 | E13: =E6*Inputs!$B$14*Inputs!$B$26*Inputs!$B$27 -> 4378550 | F13: =F6*Inputs!$B$14*Inputs!$B$26*Inputs!$B$27 -> 4911500 | G13: =G6*Inputs!$B$14*Inputs!$B$26*Inputs!$B$27 -> 5423550 | H13: =H6*Inputs!$B$14*Inputs!$B$26*Inputs!$B$27 -> 5925150 | I13: =I6*Inputs!$B$14*Inputs!$B$26*Inputs!$B$27 -> 6426750 | ... M13: =M6*Inputs!$B$14*Inputs!$B$26*Inputs!$B$27 -> 8401800 | N13: =SUM(B13:M13) -> 67402500
A14: Comisiones reservas (Premium) | B14: =B7*Inputs!$B$15*Inputs!$B$26*Inputs!$B$27 -> 1170400 | C14: =C7*Inputs!$B$15*Inputs!$B$26*Inputs!$B$27 -> 1755600 | D14: =D7*Inputs!$B$15*Inputs!$B$26*Inputs!$B$27 -> 2340800 | E14: =E7*Inputs!$B$15*Inputs!$B$26*Inputs!$B$27 -> 2967800 | F14: =F7*Inputs!$B$15*Inputs!$B$26*Inputs!$B$27 -> 3636600 | G14: =G7*Inputs!$B$15*Inputs!$B$26*Inputs!$B$27 -> 4305400 | H14: =H7*Inputs!$B$15*Inputs!$B$26*Inputs!$B$27 -> 5016000 | I14: =I7*Inputs!$B$15*Inputs!$B$26*Inputs!$B$27 -> 5726600 | ... M14: =M7*Inputs!$B$15*Inputs!$B$26*Inputs!$B$27 -> 8778000 | N14: =SUM(B14:M14) -> 57391400
A15: Suscripciones Premium | B15: =B7*Inputs!$B$25 -> 921200 | C15: =C7*Inputs!$B$25 -> 1381800 | D15: =D7*Inputs!$B$25 -> 1842400 | E15: =E7*Inputs!$B$25 -> 2335900 | F15: =F7*Inputs!$B$25 -> 2862300 | G15: =G7*Inputs!$B$25 -> 3388700 | H15: =H7*Inputs!$B$25 -> 3948000 | I15: =I7*Inputs!$B$25 -> 4507300 | ... M15: =M7*Inputs!$B$25 -> 6909000 | N15: =SUM(B15:M15) -> 45171700
A16: Revenue B2B (publicidad + SaaS) | B16: =B8*Inputs!$B$29 -> 0 | C16: =C8*Inputs!$B$29 -> 0 | D16: =D8*Inputs!$B$29 -> 1400000 | E16: =E8*Inputs!$B$29 -> 2100000 | F16: =F8*Inputs!$B$29 -> 2800000 | G16: =G8*Inputs!$B$29 -> 3500000 | H16: =H8*Inputs!$B$29 -> 4200000 | I16: =I8*Inputs!$B$29 -> 4900000 | ... M16: =M8*Inputs!$B$29 -> 7700000 | N16: =SUM(B16:M16) -> 45500000
A17: TOTAL INGRESOS | B17: =SUM(B13:B16) -> 4725000 | C17: =SUM(C13:C16) -> 6387350 | D17: =SUM(D13:D16) -> 9407900 | E17: =SUM(E13:E16) -> 11782250 | F17: =SUM(F13:F16) -> 14210400 | G17: =SUM(G13:G16) -> 16617650 | H17: =SUM(H13:H16) -> 19089150 | I17: =SUM(I13:I16) -> 21560650 | ... M17: =SUM(M13:M16) -> 31788800 | N17: =SUM(B17:M17) -> 215465600
A19: Costo de Ventas (COGS - Variables)
A20: Costo pasarela Wompi | B20: =(B6*Inputs!$B$14+B7*Inputs!$B$15)*Inputs!$B$28 -> 1960140 | C20: =(C6*Inputs!$B$14+C7*Inputs!$B$15)*Inputs!$B$28 -> 2579415 | D20: =(D6*Inputs!$B$14+D7*Inputs!$B$15)*Inputs!$B$28 -> 3177150 | E20: =(E6*Inputs!$B$14+E7*Inputs!$B$15)*Inputs!$B$28 -> 3785655 | F20: =(F6*Inputs!$B$14+F7*Inputs!$B$15)*Inputs!$B$28 -> 4404930 | G20: =(G6*Inputs!$B$14+G7*Inputs!$B$15)*Inputs!$B$28 -> 5013435 | H20: =(H6*Inputs!$B$14+H7*Inputs!$B$15)*Inputs!$B$28 -> 5638095 | I20: =(I6*Inputs!$B$14+I7*Inputs!$B$15)*Inputs!$B$28 -> 6262755 | ... M20: =(M6*Inputs!$B$14+M7*Inputs!$B$15)*Inputs!$B$28 -> 8852940 | N20: =SUM(B20:M20) -> 64307670
A21: Costo IA marginal (vLLM GPU) | B21: =(B6*Inputs!$B$18+B7*Inputs!$B$19)*Inputs!$B$20 -> 21280 | C21: =(C6*Inputs!$B$18+C7*Inputs!$B$19)*Inputs!$B$20 -> 29240 | D21: =(D6*Inputs!$B$18+D7*Inputs!$B$19)*Inputs!$B$20 -> 37040 | E21: =(E6*Inputs!$B$18+E7*Inputs!$B$19)*Inputs!$B$20 -> 45160 | F21: =(F6*Inputs!$B$18+F7*Inputs!$B$19)*Inputs!$B$20 -> 53600 | G21: =(G6*Inputs!$B$18+G7*Inputs!$B$19)*Inputs!$B$20 -> 61960 | H21: =(H6*Inputs!$B$18+H7*Inputs!$B$19)*Inputs!$B$20 -> 70680 | I21: =(I6*Inputs!$B$18+I7*Inputs!$B$19)*Inputs!$B$20 -> 79400 | ... M21: =(M6*Inputs!$B$18+M7*Inputs!$B$19)*Inputs!$B$20 -> 116160 | N21: =SUM(B21:M21) -> 807200
A22: APIs externas (variable por usuario) | B22: =B10*Inputs!$B$44 -> 201600 | C22: =C10*Inputs!$B$44 -> 254160 | D22: =D10*Inputs!$B$44 -> 303840 | E22: =E10*Inputs!$B$44 -> 352800 | F22: =F10*Inputs!$B$44 -> 401040 | G22: =G10*Inputs!$B$44 -> 447840 | H22: =H10*Inputs!$B$44 -> 494640 | I22: =I10*Inputs!$B$44 -> 541440 | ... M22: =M10*Inputs!$B$44 -> 730080 | N22: =SUM(B22:M22) -> 5632560
A23: TOTAL COGS | B23: =SUM(B20:B22) -> 2183020 | C23: =SUM(C20:C22) -> 2862815 | D23: =SUM(D20:D22) -> 3518030 | E23: =SUM(E20:E22) -> 4183615 | F23: =SUM(F20:F22) -> 4859570 | G23: =SUM(G20:G22) -> 5523235 | H23: =SUM(H20:H22) -> 6203415 | I23: =SUM(I20:I22) -> 6883595 | ... M23: =SUM(M20:M22) -> 9699180 | N23: =SUM(B23:M23) -> 70747430
A24: MARGEN BRUTO
A25: MARGEN BRUTO | B25: =B17-B23 -> 2541980 | C25: =C17-C23 -> 3524535 | D25: =D17-D23 -> 5889870 | E25: =E17-E23 -> 7598635 | F25: =F17-F23 -> 9350830 | G25: =G17-G23 -> 11094415 | H25: =H17-H23 -> 12885735 | I25: =I17-I23 -> 14677055 | ... M25: =M17-M23 -> 22089620 | N25: =SUM(B25:M25) -> 144718170
A26: % Margen Bruto | B26: =IFERROR(B25/B17,0) -> 0.53798519 | C26: =IFERROR(C25/C17,0) -> 0.55179926 | D26: =IFERROR(D25/D17,0) -> 0.62605576 | E26: =IFERROR(E25/E17,0) -> 0.64492223 | F26: =IFERROR(F25/F17,0) -> 0.65802722 | G26: =IFERROR(G25/G17,0) -> 0.6676284 | H26: =IFERROR(H25/H17,0) -> 0.67502927 | I26: =IFERROR(I25/I17,0) -> 0.68073342 | ... N26: =IFERROR(N25/N17,0) -> 0.67165325
A28: Gastos Operativos (OPEX Fijo)
A29: Talento humano | B29: =Inputs!$B$40 -> 22675000 | C29: =Inputs!$B$40 -> 22675000 | D29: =Inputs!$B$40 -> 22675000 | E29: =Inputs!$B$40 -> 22675000 | F29: =Inputs!$B$40 -> 22675000 | G29: =Inputs!$B$40 -> 22675000 | H29: =Inputs!$B$40 -> 22675000 | I29: =Inputs!$B$40 -> 22675000 | ... M29: =Inputs!$B$40 -> 22675000 | N29: =SUM(B29:M29) -> 272100000
A30: Infraestructura Cloud AWS (corregida) | B30: =Inputs!$B$41 -> 2602542 | C30: =Inputs!$B$41 -> 2602542 | D30: =Inputs!$B$41 -> 2602542 | E30: =Inputs!$B$41 -> 2602542 | F30: =Inputs!$B$41 -> 2602542 | G30: =Inputs!$B$41 -> 2602542 | H30: =Inputs!$B$41 -> 2602542 | I30: =Inputs!$B$41 -> 2602542 | ... M30: =Inputs!$B$41 -> 2602542 | N30: =SUM(B30:M30) -> 31230504
A31: Marketing digital (base) | B31: =Inputs!$B$42 -> 1900000 | C31: =Inputs!$B$42 -> 1900000 | D31: =Inputs!$B$42 -> 1900000 | E31: =Inputs!$B$42 -> 1900000 | F31: =Inputs!$B$42 -> 1900000 | G31: =Inputs!$B$42 -> 1900000 | H31: =Inputs!$B$42 -> 1900000 | I31: =Inputs!$B$42 -> 1900000 | ... N31: =Inputs!$B$42 -> 1900000
A32: APIs externas (costo mínimo fijo) | B32: =Inputs!$B$43 -> 2400000 | C32: =Inputs!$B$43 -> 2400000 | D32: =Inputs!$B$43 -> 2400000 | E32: =Inputs!$B$43 -> 2400000 | F32: =Inputs!$B$43 -> 2400000 | G32: =Inputs!$B$43 -> 2400000 | H32: =Inputs!$B$43 -> 2400000 | I32: =Inputs!$B$43 -> 2400000 | ... N32: =Inputs!$B$43 -> 2400000
A33: CAC spend (adquisición) | B33: =B5*(1-Inputs!$B$9)*Inputs!$B$35+B5*Inputs!$B$9*Inputs!$B$36+B9*Inputs!$B$37 -> 1800000 | C33: =C5*(1-Inputs!$B$9)*Inputs!$B$35+C5*Inputs!$B$9*Inputs!$B$36+C9*Inputs!$B$37 -> 1890000 | D33: =D5*(1-Inputs!$B$9)*Inputs!$B$35+D5*Inputs!$B$9*Inputs!$B$36+D9*Inputs!$B$37 -> 5580000 | E33: =E5*(1-Inputs!$B$9)*Inputs!$B$35+E5*Inputs!$B$9*Inputs!$B$36+E9*Inputs!$B$37 -> 3888000 | F33: =F5*(1-Inputs!$B$9)*Inputs!$B$35+F5*Inputs!$B$9*Inputs!$B$36+F9*Inputs!$B$37 -> 3996000 | G33: =G5*(1-Inputs!$B$9)*Inputs!$B$35+G5*Inputs!$B$9*Inputs!$B$36+G9*Inputs!$B$37 -> 4104000 | H33: =H5*(1-Inputs!$B$9)*Inputs!$B$35+H5*Inputs!$B$9*Inputs!$B$36+H9*Inputs!$B$37 -> 4212000 | I33: =I5*(1-Inputs!$B$9)*Inputs!$B$35+I5*Inputs!$B$9*Inputs!$B$36+I9*Inputs!$B$37 -> 4338000 | ... M33: =M5*(1-Inputs!$B$9)*Inputs!$B$35+M5*Inputs!$B$9*Inputs!$B$36+M9*Inputs!$B$37 -> 4878000 | N33: =SUM(B33:M33) -> 48474000
A34: TOTAL OPEX | B34: =SUM(B29:B33) -> 31377542 | C34: =SUM(C29:C33) -> 31467542 | D34: =SUM(D29:D33) -> 35157542 | E34: =SUM(E29:E33) -> 33465542 | F34: =SUM(F29:F33) -> 33573542 | G34: =SUM(G29:G33) -> 33681542 | H34: =SUM(H29:H33) -> 33789542 | I34: =SUM(I29:I33) -> 33915542 | ... M34: =SUM(M29:M33) -> 34455542 | N34: =SUM(B34:M34) -> 403404504
A35: Rentabilidad
A36: EBITDA (Utilidad Operativa Bruta) | B36: =B25-B34 -> -28835562 | C36: =C25-C34 -> -27943007 | D36: =D25-D34 -> -29267672 | E36: =E25-E34 -> -25866907 | F36: =F25-F34 -> -24222712 | G36: =G25-G34 -> -22587127 | H36: =H25-H34 -> -20903807 | I36: =I25-I34 -> -19238487 | ... M36: =M25-M34 -> -12365922 | N36: =SUM(B36:M36) -> -258686334
A37: % EBITDA sobre ingresos | B37: =IFERROR(B36/B17,0) -> -6.1027644 | C37: =IFERROR(C36/C17,0) -> -4.3747418 | D37: =IFERROR(D36/D17,0) -> -3.1109676 | E37: =IFERROR(E36/E17,0) -> -2.1954132 | F37: =IFERROR(F36/F17,0) -> -1.7045764 | G37: =IFERROR(G36/G17,0) -> -1.3592251 | H37: =IFERROR(H36/H17,0) -> -1.0950622 | I37: =IFERROR(I36/I17,0) -> -0.89229624 | ... N37: =IFERROR(N36/N17,0) -> -1.2005923
A38: Amortización CAPEX | B38: =Inputs!$B$47/Inputs!$B$48 -> 6057976.9 | C38: =Inputs!$B$47/Inputs!$B$48 -> 6057976.9 | D38: =Inputs!$B$47/Inputs!$B$48 -> 6057976.9 | E38: =Inputs!$B$47/Inputs!$B$48 -> 6057976.9 | F38: =Inputs!$B$47/Inputs!$B$48 -> 6057976.9 | G38: =Inputs!$B$47/Inputs!$B$48 -> 6057976.9 | H38: =Inputs!$B$47/Inputs!$B$48 -> 6057976.9 | I38: =Inputs!$B$47/Inputs!$B$48 -> 6057976.9 | ... N38: =Inputs!$B$47/Inputs!$B$48 -> 6057976.9
A39: EBIT (Utilidad Operativa Neta) | B39: =B36-B38 -> -34893539 | C39: =C36-C38 -> -34000984 | D39: =D36-D38 -> -35325649 | E39: =E36-E38 -> -31924884 | F39: =F36-F38 -> -30280689 | G39: =G36-G38 -> -28645104 | H39: =H36-H38 -> -26961784 | I39: =I36-I38 -> -25296464 | ... M39: =M36-M38 -> -18423899 | N39: =SUM(B39:M39) -> -3.3138206e+08
A40: Impuesto de renta (33%) | B40: =IF(B39>0,B39*Inputs!$B$52,0) -> 0 | C40: =IF(C39>0,C39*Inputs!$B$52,0) -> 0 | D40: =IF(D39>0,D39*Inputs!$B$52,0) -> 0 | E40: =IF(E39>0,E39*Inputs!$B$52,0) -> 0 | F40: =IF(F39>0,F39*Inputs!$B$52,0) -> 0 | G40: =IF(G39>0,G39*Inputs!$B$52,0) -> 0 | H40: =IF(H39>0,H39*Inputs!$B$52,0) -> 0 | I40: =IF(I39>0,I39*Inputs!$B$52,0) -> 0 | ... M40: =IF(M39>0,M39*Inputs!$B$52,0) -> 0 | N40: =SUM(B40:M40) -> 0
A41: UTILIDAD NETA | B41: =B39-B40 -> -34893539 | C41: =C39-C40 -> -34000984 | D41: =D39-D40 -> -35325649 | E41: =E39-E40 -> -31924884 | F41: =F39-F40 -> -30280689 | G41: =G39-G40 -> -28645104 | H41: =H39-H40 -> -26961784 | I41: =I39-I40 -> -25296464 | ... M41: =M39-M40 -> -18423899 | N41: =SUM(B41:M41) -> -3.3138206e+08
A42: % Margen Neto | B42: =IFERROR(B41/B17,0) -> -7.384876 | C42: =IFERROR(C41/C17,0) -> -5.3231753 | D42: =IFERROR(D41/D17,0) -> -3.754892 | E42: =IFERROR(E41/E17,0) -> -2.7095745 | F42: =IFERROR(F41/F17,0) -> -2.1308822 | G42: =IFERROR(G41/G17,0) -> -1.7237759 | H42: =IFERROR(H41/H17,0) -> -1.4124141 | I42: =IFERROR(I41/I17,0) -> -1.17327 | ... N42: =IFERROR(N41/N17,0) -> -1.5379813

Sheet Cash Flow
A1: Flujo de Caja - 12 Meses
A3: Concepto (COP) | B3: Mes 1 | C3: Mes 2 | D3: Mes 3 | E3: Mes 4 | F3: Mes 5 | G3: Mes 6 | H3: Mes 7 | I3: Mes 8 | J3: Mes 9 | K3: Mes 10 | L3: Mes 11 | M3: Mes 12 | N3: Año 1 Total
A4: Actividades Operativas
A5: EBITDA (de PyG) | B5: ='P&G 12 Meses'!B36 -> -28835562 | C5: ='P&G 12 Meses'!C36 -> -27943007 | D5: ='P&G 12 Meses'!D36 -> -29267672 | E5: ='P&G 12 Meses'!E36 -> -25866907 | F5: ='P&G 12 Meses'!F36 -> -24222712 | G5: ='P&G 12 Meses'!G36 -> -22587127 | H5: ='P&G 12 Meses'!H36 -> -20903807 | I5: ='P&G 12 Meses'!I36 -> -19238487 | ... M5: ='P&G 12 Meses'!M36 -> -12365922 | N5: =SUM(B5:M5) -> -258686334
A6: Cambio capital de trabajo (AR lag 5%) | B6: =-'P&G 12 Meses'!B17*0.05 -> -236250 | C6: =-('P&G 12 Meses'!C17 - 'P&G 12 Meses'!B17)*0.05 -> -83117.5 | D6: =-('P&G 12 Meses'!D17 - 'P&G 12 Meses'!C17)*0.05 -> -151027.5 | E6: =-('P&G 12 Meses'!E17 - 'P&G 12 Meses'!D17)*0.05 -> -118717.5 | F6: =-('P&G 12 Meses'!F17 - 'P&G 12 Meses'!E17)*0.05 -> -121407.5 | G6: =-('P&G 12 Meses'!G17 - 'P&G 12 Meses'!F17)*0.05 -> -120362.5 | H6: =-('P&G 12 Meses'!H17 - 'P&G 12 Meses'!G17)*0.05 -> -123575 | I6: =-('P&G 12 Meses'!I17 - 'P&G 12 Meses'!H17)*0.05 -> -123575 | J6: =-('P&G 12 Meses'!J17 - 'P&G 12 Meses'!I17)*0.05 -> -126787.5 | ... M6: =-('P&G 12 Meses'!M17 - 'P&G 12 Meses'!L17)*0.05 -> -131045 | N6: =SUM(B6:M6) -> -1589440
A7: Impuestos pagados | B7: =-'P&G 12 Meses'!C40 -> 0 | C7: =-'P&G 12 Meses'!D40 -> 0 | D7: =-'P&G 12 Meses'!E40 -> 0 | E7: =-'P&G 12 Meses'!F40 -> 0 | F7: =-'P&G 12 Meses'!G40 -> 0 | G7: =-'P&G 12 Meses'!H40 -> 0 | H7: =-'P&G 12 Meses'!I40 -> 0 | I7: =-'P&G 12 Meses'!J40 -> 0 | ... M7: =-'P&G 12 Meses'!N40 -> 0 | N7: =SUM(B7:M7) -> 0
A8: FLUJO CAJA OPERATIVO | B8: =B5+B6+B7 -> -29071812 | C8: =C5+C6+C7 -> -28026124 | D8: =D5+D6+D7 -> -29418700 | E8: =E5+E6+E7 -> -25985624 | F8: =F5+F6+F7 -> -24344120 | G8: =G5+G6+G7 -> -22707490 | H8: =H5+H6+H7 -> -21027382 | I8: =I5+I6+I7 -> -19362062 | ... M8: =M5+M6+M7 -> -12496967 | N8: =SUM(B8:M8) -> -260275774
A10: Actividades de Inversión (CAPEX)
A11: CAPEX inicial (desembolso mes 0/1) | B11: =-Inputs!$B$47 -> -218087168 | C11: =0 -> 0 | D11: =0 -> 0 | E11: =0 -> 0 | F11: =0 -> 0 | G11: =0 -> 0 | H11: =0 -> 0 | I11: =0 -> 0 | J11: =0 -> 0 | ... M11: =0 -> 0 | N11: =SUM(B11:M11) -> -218087168
A12: FLUJO CAJA INVERSIÓN | B12: =B11 -> -218087168 | C12: =C11 -> 0 | D12: =D11 -> 0 | E12: =E11 -> 0 | F12: =F11 -> 0 | G12: =G11 -> 0 | H12: =H11 -> 0 | I12: =I11 -> 0 | ... M12: =M11 -> 0 | N12: =SUM(B12:M12) -> -218087168
A14: Actividades de Financiamiento
A15: Aporte de capital / financiamiento | B15: =0 -> 0 | C15: =0 -> 0 | D15: =0 -> 0 | E15: =0 -> 0 | F15: =0 -> 0 | G15: =0 -> 0 | H15: =0 -> 0 | I15: =0 -> 0 | ... M15: =0 -> 0 | N15: =SUM(B15:M15) -> 0
A16: FLUJO CAJA FINANCIERO | B16: =B15 -> 0 | C16: =C15 -> 0 | D16: =D15 -> 0 | E16: =E15 -> 0 | F16: =F15 -> 0 | G16: =G15 -> 0 | H16: =H15 -> 0 | I16: =I15 -> 0 | ... M16: =M15 -> 0 | N16: =SUM(B16:M16) -> 0
A18: Resumen de Caja
A19: FLUJO NETO DEL PERÍODO | B19: =B8+B12+B16 -> -247158980 | C19: =C8+C12+C16 -> -28026124 | D19: =D8+D12+D16 -> -29418700 | E19: =E8+E12+E16 -> -25985624 | F19: =F8+F12+F16 -> -24344120 | G19: =G8+G12+G16 -> -22707490 | H19: =H8+H12+H16 -> -21027382 | I19: =I8+I12+I16 -> -19362062 | ... M19: =M8+M12+M16 -> -12496967 | N19: =SUM(B19:M19) -> -478362942
A20: SALDO CAJA ACUMULADO | B20: =B19 -> -247158980 | C20: =B20+C19 -> -2.751851e+08 | D20: =C20+D19 -> -304603804 | E20: =D20+E19 -> -3.3058943e+08 | F20: =E20+F19 -> -354933548 | G20: =F20+G19 -> -3.7764104e+08 | H20: =G20+H19 -> -3.9866842e+08 | I20: =H20+I19 -> -4.1803048e+08 | J20: =I20+J19 -> -435682701 | ... M20: =L20+M19 -> -478362942 | N20: =SUM(B20:M20) -> -4538344287
A21: Saldo mínimo requerido (buffer operativo) | B21: =Inputs!$B$40*2 -> 45350000 | C21: =Inputs!$B$40*2 -> 45350000 | D21: =Inputs!$B$40*2 -> 45350000 | E21: =Inputs!$B$40*2 -> 45350000 | F21: =Inputs!$B$40*2 -> 45350000 | G21: =Inputs!$B$40*2 -> 45350000 | H21: =Inputs!$B$40*2 -> 45350000 | I21: =Inputs!$B$40*2 -> 45350000 | ... M21: =Inputs!$B$40*2 -> 45350000 | N21: =SUM(B21:M21) -> 544200000

Sheet P&G 36 Meses
A1: Estado de Resultados (P&G) Proyectado - 36 Meses
A3: Concepto (COP) | B3: Mes 1 | C3: Mes 2 | D3: Mes 3 | E3: Mes 4 | F3: Mes 5 | G3: Mes 6 | H3: Mes 7 | I3: Mes 8 | J3: Mes 9 | K3: Mes 10 | L3: Mes 11 | M3: Mes 12 | N3: Mes 13 | O3: Mes 14 | P3: Mes 15 | Q3: Mes 16 | R3: Mes 17 | S3: Mes 18 | T3: Mes 19 | U3: Mes 20 | V3: Mes 21 | W3: Mes 22 | X3: Mes 23 | Y3: Mes 24 | Z3: Mes 25 | AA3: Mes 26 | AB3: Mes 27 | AC3: Mes 28 | AD3: Mes 29 | AE3: Mes 30 | AF3: Mes 31 | AG3: Mes 32 | AH3: Mes 33 | AI3: Mes 34 | AJ3: Mes 35 | AK3: Mes 36 | AL3: Total 36m
A4: Usuarios
A5: Nuevos usuarios adquiridos | B5: =ROUND(Inputs!$B$7*(1+Inputs!$B$8)^0,0) -> 100 | C5: =ROUND(Inputs!$B$7*(1+Inputs!$B$8)^1,0) -> 105 | D5: =ROUND(Inputs!$B$7*(1+Inputs!$B$8)^2,0) -> 110 | E5: =ROUND(Inputs!$B$7*(1+Inputs!$B$8)^3,0) -> 116 | F5: =ROUND(Inputs!$B$7*(1+Inputs!$B$8)^4,0) -> 122 | G5: =ROUND(Inputs!$B$7*(1+Inputs!$B$8)^5,0) -> 128 | H5: =ROUND(Inputs!$B$7*(1+Inputs!$B$8)^6,0) -> 134 | I5: =ROUND(Inputs!$B$7*(1+Inputs!$B$8)^7,0) -> 141 | J5: =ROUND(Inputs!$B$7*(1+Inputs!$B$8)^8,0) -> 148 | K5: =ROUND(Inputs!$B$7*(1+Inputs!$B$8)^9,0) -> 155 | L5: =ROUND(Inputs!$B$7*(1+Inputs!$B$8)^10,0) -> 163 | M5: =ROUND(Inputs!$B$7*(1+Inputs!$B$8)^11,0) -> 171 | N5: =ROUND(Inputs!$B$7*(1+Inputs!$B$8)^12,0) -> 180 | O5: =ROUND(Inputs!$B$7*(1+Inputs!$B$8)^13,0) -> 189 | P5: =ROUND(Inputs!$B$7*(1+Inputs!$B$8)^14,0) -> 198 | Q5: =ROUND(Inputs!$B$7*(1+Inputs!$B$8)^15,0) -> 208 | R5: =ROUND(Inputs!$B$7*(1+Inputs!$B$8)^16,0) -> 218 | S5: =ROUND(Inputs!$B$7*(1+Inputs!$B$8)^17,0) -> 229 | T5: =ROUND(Inputs!$B$7*(1+Inputs!$B$8)^18,0) -> 241 | U5: =ROUND(Inputs!$B$7*(1+Inputs!$B$8)^19,0) -> 253 | V5: =ROUND(Inputs!$B$7*(1+Inputs!$B$8)^20,0) -> 265 | W5: =ROUND(Inputs!$B$7*(1+Inputs!$B$8)^21,0) -> 279 | X5: =ROUND(Inputs!$B$7*(1+Inputs!$B$8)^22,0) -> 293 | Y5: =ROUND(Inputs!$B$7*(1+Inputs!$B$8)^23,0) -> 307 | Z5: =ROUND(Inputs!$B$7*(1+Inputs!$B$8)^24,0) -> 323 | AA5: =ROUND(Inputs!$B$7*(1+Inputs!$B$8)^25,0) -> 339 | AB5: =ROUND(Inputs!$B$7*(1+Inputs!$B$8)^26,0) -> 356 | AC5: =ROUND(Inputs!$B$7*(1+Inputs!$B$8)^27,0) -> 373 | AD5: =ROUND(Inputs!$B$7*(1+Inputs!$B$8)^28,0) -> 392 | AE5: =ROUND(Inputs!$B$7*(1+Inputs!$B$8)^29,0) -> 412 | AF5: =ROUND(Inputs!$B$7*(1+Inputs!$B$8)^30,0) -> 432 | AG5: =ROUND(Inputs!$B$7*(1+Inputs!$B$8)^31,0) -> 454 | AH5: =ROUND(Inputs!$B$7*(1+Inputs!$B$8)^32,0) -> 476 | AI5: =ROUND(Inputs!$B$7*(1+Inputs!$B$8)^33,0) -> 500 | AJ5: =ROUND(Inputs!$B$7*(1+Inputs!$B$8)^34,0) -> 525 | AK5: =ROUND(Inputs!$B$7*(1+Inputs!$B$8)^35,0) -> 552 | AL5: =SUM(B5:AK5) -> 9587
A6: Usuarios Free (neto fin de mes) | B6: =ROUND((Inputs!$B$6*(1-Inputs!$B$9))+B5*(1-Inputs!$B$9),0) -> 252 | C6: =ROUND(B6*(1-Inputs!$B$11-Inputs!$B$10)+C5*(1-Inputs!$B$9),0) -> 311 | D6: =ROUND(C6*(1-Inputs!$B$11-Inputs!$B$10)+D5*(1-Inputs!$B$9),0) -> 366 | E6: =ROUND(D6*(1-Inputs!$B$11-Inputs!$B$10)+E5*(1-Inputs!$B$9),0) -> 419 | F6: =ROUND(E6*(1-Inputs!$B$11-Inputs!$B$10)+F5*(1-Inputs!$B$9),0) -> 470 | G6: =ROUND(F6*(1-Inputs!$B$11-Inputs!$B$10)+G5*(1-Inputs!$B$9),0) -> 519 | H6: =ROUND(G6*(1-Inputs!$B$11-Inputs!$B$10)+H5*(1-Inputs!$B$9),0) -> 567 | I6: =ROUND(H6*(1-Inputs!$B$11-Inputs!$B$10)+I5*(1-Inputs!$B$9),0) -> 615 | J6: =ROUND(I6*(1-Inputs!$B$11-Inputs!$B$10)+J5*(1-Inputs!$B$9),0) -> 662 | ... AK6: =ROUND(AJ6*(1-Inputs!$B$11-Inputs!$B$10)+AK5*(1-Inputs!$B$9),0) -> 2741 | AL6: =SUM(B6:AK6) -> 45920
A7: Usuarios Premium (neto fin de mes) | B7: =ROUND((Inputs!$B$6*Inputs!$B$9)+B5*Inputs!$B$9,0) -> 28 | C7: =ROUND(B7*(1-Inputs!$B$12)+B6*Inputs!$B$10+C5*Inputs!$B$9,0) -> 42 | D7: =ROUND(C7*(1-Inputs!$B$12)+C6*Inputs!$B$10+D5*Inputs!$B$9,0) -> 56 | E7: =ROUND(D7*(1-Inputs!$B$12)+D6*Inputs!$B$10+E5*Inputs!$B$9,0) -> 71 | F7: =ROUND(E7*(1-Inputs!$B$12)+E6*Inputs!$B$10+F5*Inputs!$B$9,0) -> 87 | G7: =ROUND(F7*(1-Inputs!$B$12)+F6*Inputs!$B$10+G5*Inputs!$B$9,0) -> 103 | H7: =ROUND(G7*(1-Inputs!$B$12)+G6*Inputs!$B$10+H5*Inputs!$B$9,0) -> 120 | I7: =ROUND(H7*(1-Inputs!$B$12)+H6*Inputs!$B$10+I5*Inputs!$B$9,0) -> 137 | J7: =ROUND(I7*(1-Inputs!$B$12)+I6*Inputs!$B$10+J5*Inputs!$B$9,0) -> 155 | ... AK7: =ROUND(AJ7*(1-Inputs!$B$12)+AJ6*Inputs!$B$10+AK5*Inputs!$B$9,0) -> 924 | AL7: =SUM(B7:AK7) -> 14034
A8: Clientes B2B (neto) | B8: =IF(1>=Inputs!$B$30,Inputs!$B$31,0) -> 0 | C8: =IF(2>=Inputs!$B$30,ROUND(B8*(1-Inputs!$B$13)+IF(2=Inputs!$B$30,Inputs!$B$31,Inputs!$B$32),0),0) -> 0 | D8: =IF(3>=Inputs!$B$30,ROUND(C8*(1-Inputs!$B$13)+IF(3=Inputs!$B$30,Inputs!$B$31,Inputs!$B$32),0),0) -> 2 | E8: =IF(4>=Inputs!$B$30,ROUND(D8*(1-Inputs!$B$13)+IF(4=Inputs!$B$30,Inputs!$B$31,Inputs!$B$32),0),0) -> 3 | F8: =IF(5>=Inputs!$B$30,ROUND(E8*(1-Inputs!$B$13)+IF(5=Inputs!$B$30,Inputs!$B$31,Inputs!$B$32),0),0) -> 4 | G8: =IF(6>=Inputs!$B$30,ROUND(F8*(1-Inputs!$B$13)+IF(6=Inputs!$B$30,Inputs!$B$31,Inputs!$B$32),0),0) -> 5 | H8: =IF(7>=Inputs!$B$30,ROUND(G8*(1-Inputs!$B$13)+IF(7=Inputs!$B$30,Inputs!$B$31,Inputs!$B$32),0),0) -> 6 | I8: =IF(8>=Inputs!$B$30,ROUND(H8*(1-Inputs!$B$13)+IF(8=Inputs!$B$30,Inputs!$B$31,Inputs!$B$32),0),0) -> 7 | J8: =IF(9>=Inputs!$B$30,ROUND(I8*(1-Inputs!$B$13)+IF(9=Inputs!$B$30,Inputs!$B$31,Inputs!$B$32),0),0) -> 8 | K8: =IF(10>=Inputs!$B$30,ROUND(J8*(1-Inputs!$B$13)+IF(10=Inputs!$B$30,Inputs!$B$31,Inputs!$B$32),0),0) -> 9 | L8: =IF(11>=Inputs!$B$30,ROUND(K8*(1-Inputs!$B$13)+IF(11=Inputs!$B$30,Inputs!$B$31,Inputs!$B$32),0),0) -> 10 | M8: =IF(12>=Inputs!$B$30,ROUND(L8*(1-Inputs!$B$13)+IF(12=Inputs!$B$30,Inputs!$B$31,Inputs!$B$32),0),0) -> 11 | N8: =IF(13>=Inputs!$B$30,ROUND(M8*(1-Inputs!$B$13)+IF(13=Inputs!$B$30,Inputs!$B$31,Inputs!$B$32),0),0) -> 12 | O8: =IF(14>=Inputs!$B$30,ROUND(N8*(1-Inputs!$B$13)+IF(14=Inputs!$B$30,Inputs!$B$31,Inputs!$B$32),0),0) -> 13 | P8: =IF(15>=Inputs!$B$30,ROUND(O8*(1-Inputs!$B$13)+IF(15=Inputs!$B$30,Inputs!$B$31,Inputs!$B$32),0),0) -> 14 | Q8: =IF(16>=Inputs!$B$30,ROUND(P8*(1-Inputs!$B$13)+IF(16=Inputs!$B$30,Inputs!$B$31,Inputs!$B$32),0),0) -> 15 | R8: =IF(17>=Inputs!$B$30,ROUND(Q8*(1-Inputs!$B$13)+IF(17=Inputs!$B$30,Inputs!$B$31,Inputs!$B$32),0),0) -> 16 | S8: =IF(18>=Inputs!$B$30,ROUND(R8*(1-Inputs!$B$13)+IF(18=Inputs!$B$30,Inputs!$B$31,Inputs!$B$32),0),0) -> 17 | T8: =IF(19>=Inputs!$B$30,ROUND(S8*(1-Inputs!$B$13)+IF(19=Inputs!$B$30,Inputs!$B$31,Inputs!$B$32),0),0) -> 17 | U8: =IF(20>=Inputs!$B$30,ROUND(T8*(1-Inputs!$B$13)+IF(20=Inputs!$B$30,Inputs!$B$31,Inputs!$B$32),0),0) -> 17 | V8: =IF(21>=Inputs!$B$30,ROUND(U8*(1-Inputs!$B$13)+IF(21=Inputs!$B$30,Inputs!$B$31,Inputs!$B$32),0),0) -> 17 | W8: =IF(22>=Inputs!$B$30,ROUND(V8*(1-Inputs!$B$13)+IF(22=Inputs!$B$30,Inputs!$B$31,Inputs!$B$32),0),0) -> 17 | X8: =IF(23>=Inputs!$B$30,ROUND(W8*(1-Inputs!$B$13)+IF(23=Inputs!$B$30,Inputs!$B$31,Inputs!$B$32),0),0) -> 17 | Y8: =IF(24>=Inputs!$B$30,ROUND(X8*(1-Inputs!$B$13)+IF(24=Inputs!$B$30,Inputs!$B$31,Inputs!$B$32),0),0) -> 17 | Z8: =IF(25>=Inputs!$B$30,ROUND(Y8*(1-Inputs!$B$13)+IF(25=Inputs!$B$30,Inputs!$B$31,Inputs!$B$32),0),0) -> 17 | AA8: =IF(26>=Inputs!$B$30,ROUND(Z8*(1-Inputs!$B$13)+IF(26=Inputs!$B$30,Inputs!$B$31,Inputs!$B$32),0),0) -> 17 | AB8: =IF(27>=Inputs!$B$30,ROUND(AA8*(1-Inputs!$B$13)+IF(27=Inputs!$B$30,Inputs!$B$31,Inputs!$B$32),0),0) -> 17 | AC8: =IF(28>=Inputs!$B$30,ROUND(AB8*(1-Inputs!$B$13)+IF(28=Inputs!$B$30,Inputs!$B$31,Inputs!$B$32),0),0) -> 17 | AD8: =IF(29>=Inputs!$B$30,ROUND(AC8*(1-Inputs!$B$13)+IF(29=Inputs!$B$30,Inputs!$B$31,Inputs!$B$32),0),0) -> 17 | AE8: =IF(30>=Inputs!$B$30,ROUND(AD8*(1-Inputs!$B$13)+IF(30=Inputs!$B$30,Inputs!$B$31,Inputs!$B$32),0),0) -> 17 | AF8: =IF(31>=Inputs!$B$30,ROUND(AE8*(1-Inputs!$B$13)+IF(31=Inputs!$B$30,Inputs!$B$31,Inputs!$B$32),0),0) -> 17 | AG8: =IF(32>=Inputs!$B$30,ROUND(AF8*(1-Inputs!$B$13)+IF(32=Inputs!$B$30,Inputs!$B$31,Inputs!$B$32),0),0) -> 17 | AH8: =IF(33>=Inputs!$B$30,ROUND(AG8*(1-Inputs!$B$13)+IF(33=Inputs!$B$30,Inputs!$B$31,Inputs!$B$32),0),0) -> 17 | AI8: =IF(34>=Inputs!$B$30,ROUND(AH8*(1-Inputs!$B$13)+IF(34=Inputs!$B$30,Inputs!$B$31,Inputs!$B$32),0),0) -> 17 | AJ8: =IF(35>=Inputs!$B$30,ROUND(AI8*(1-Inputs!$B$13)+IF(35=Inputs!$B$30,Inputs!$B$31,Inputs!$B$32),0),0) -> 17 | AK8: =IF(36>=Inputs!$B$30,ROUND(AJ8*(1-Inputs!$B$13)+IF(36=Inputs!$B$30,Inputs!$B$31,Inputs!$B$32),0),0) -> 17 | AL8: =SUM(B8:AK8) -> 458
A9: Nuevos clientes B2B | B9: =IF(1>=Inputs!$B$30,Inputs!$B$31,0) -> 0 | C9: =IF(2=Inputs!$B$30,Inputs!$B$31,IF(2>Inputs!$B$30,Inputs!$B$32,0)) -> 0 | D9: =IF(3=Inputs!$B$30,Inputs!$B$31,IF(3>Inputs!$B$30,Inputs!$B$32,0)) -> 2 | E9: =IF(4=Inputs!$B$30,Inputs!$B$31,IF(4>Inputs!$B$30,Inputs!$B$32,0)) -> 1 | F9: =IF(5=Inputs!$B$30,Inputs!$B$31,IF(5>Inputs!$B$30,Inputs!$B$32,0)) -> 1 | G9: =IF(6=Inputs!$B$30,Inputs!$B$31,IF(6>Inputs!$B$30,Inputs!$B$32,0)) -> 1 | H9: =IF(7=Inputs!$B$30,Inputs!$B$31,IF(7>Inputs!$B$30,Inputs!$B$32,0)) -> 1 | I9: =IF(8=Inputs!$B$30,Inputs!$B$31,IF(8>Inputs!$B$30,Inputs!$B$32,0)) -> 1 | J9: =IF(9=Inputs!$B$30,Inputs!$B$31,IF(9>Inputs!$B$30,Inputs!$B$32,0)) -> 1 | K9: =IF(10=Inputs!$B$30,Inputs!$B$31,IF(10>Inputs!$B$30,Inputs!$B$32,0)) -> 1 | L9: =IF(11=Inputs!$B$30,Inputs!$B$31,IF(11>Inputs!$B$30,Inputs!$B$32,0)) -> 1 | M9: =IF(12=Inputs!$B$30,Inputs!$B$31,IF(12>Inputs!$B$30,Inputs!$B$32,0)) -> 1 | N9: =IF(13=Inputs!$B$30,Inputs!$B$31,IF(13>Inputs!$B$30,Inputs!$B$32,0)) -> 1 | O9: =IF(14=Inputs!$B$30,Inputs!$B$31,IF(14>Inputs!$B$30,Inputs!$B$32,0)) -> 1 | P9: =IF(15=Inputs!$B$30,Inputs!$B$31,IF(15>Inputs!$B$30,Inputs!$B$32,0)) -> 1 | Q9: =IF(16=Inputs!$B$30,Inputs!$B$31,IF(16>Inputs!$B$30,Inputs!$B$32,0)) -> 1 | R9: =IF(17=Inputs!$B$30,Inputs!$B$31,IF(17>Inputs!$B$30,Inputs!$B$32,0)) -> 1 | S9: =IF(18=Inputs!$B$30,Inputs!$B$31,IF(18>Inputs!$B$30,Inputs!$B$32,0)) -> 1 | T9: =IF(19=Inputs!$B$30,Inputs!$B$31,IF(19>Inputs!$B$30,Inputs!$B$32,0)) -> 1 | U9: =IF(20=Inputs!$B$30,Inputs!$B$31,IF(20>Inputs!$B$30,Inputs!$B$32,0)) -> 1 | V9: =IF(21=Inputs!$B$30,Inputs!$B$31,IF(21>Inputs!$B$30,Inputs!$B$32,0)) -> 1 | W9: =IF(22=Inputs!$B$30,Inputs!$B$31,IF(22>Inputs!$B$30,Inputs!$B$32,0)) -> 1 | X9: =IF(23=Inputs!$B$30,Inputs!$B$31,IF(23>Inputs!$B$30,Inputs!$B$32,0)) -> 1 | Y9: =IF(24=Inputs!$B$30,Inputs!$B$31,IF(24>Inputs!$B$30,Inputs!$B$32,0)) -> 1 | Z9: =IF(25=Inputs!$B$30,Inputs!$B$31,IF(25>Inputs!$B$30,Inputs!$B$32,0)) -> 1 | AA9: =IF(26=Inputs!$B$30,Inputs!$B$31,IF(26>Inputs!$B$30,Inputs!$B$32,0)) -> 1 | AB9: =IF(27=Inputs!$B$30,Inputs!$B$31,IF(27>Inputs!$B$30,Inputs!$B$32,0)) -> 1 | AC9: =IF(28=Inputs!$B$30,Inputs!$B$31,IF(28>Inputs!$B$30,Inputs!$B$32,0)) -> 1 | AD9: =IF(29=Inputs!$B$30,Inputs!$B$31,IF(29>Inputs!$B$30,Inputs!$B$32,0)) -> 1 | AE9: =IF(30=Inputs!$B$30,Inputs!$B$31,IF(30>Inputs!$B$30,Inputs!$B$32,0)) -> 1 | AF9: =IF(31=Inputs!$B$30,Inputs!$B$31,IF(31>Inputs!$B$30,Inputs!$B$32,0)) -> 1 | AG9: =IF(32=Inputs!$B$30,Inputs!$B$31,IF(32>Inputs!$B$30,Inputs!$B$32,0)) -> 1 | AH9: =IF(33=Inputs!$B$30,Inputs!$B$31,IF(33>Inputs!$B$30,Inputs!$B$32,0)) -> 1 | AI9: =IF(34=Inputs!$B$30,Inputs!$B$31,IF(34>Inputs!$B$30,Inputs!$B$32,0)) -> 1 | AJ9: =IF(35=Inputs!$B$30,Inputs!$B$31,IF(35>Inputs!$B$30,Inputs!$B$32,0)) -> 1 | AK9: =IF(36=Inputs!$B$30,Inputs!$B$31,IF(36>Inputs!$B$30,Inputs!$B$32,0)) -> 1 | AL9: =SUM(B9:AK9) -> 35
A10: Total usuarios activos (Free+Premium) | B10: =B6+B7 -> 280 | C10: =C6+C7 -> 353 | D10: =D6+D7 -> 422 | E10: =E6+E7 -> 490 | F10: =F6+F7 -> 557 | G10: =G6+G7 -> 622 | H10: =H6+H7 -> 687 | I10: =I6+I7 -> 752 | ... AK10: =AK6+AK7 -> 3665 | AL10: =SUM(B10:AK10) -> 59954
A12: Ingresos
A13: Comisiones reservas (Free) | B13: =B6*Inputs!$B$14*Inputs!$B$26*Inputs!$B$27 -> 2633400 | C13: =C6*Inputs!$B$14*Inputs!$B$26*Inputs!$B$27 -> 3249950 | D13: =D6*Inputs!$B$14*Inputs!$B$26*Inputs!$B$27 -> 3824700 | E13: =E6*Inputs!$B$14*Inputs!$B$26*Inputs!$B$27 -> 4378550 | F13: =F6*Inputs!$B$14*Inputs!$B$26*Inputs!$B$27 -> 4911500 | G13: =G6*Inputs!$B$14*Inputs!$B$26*Inputs!$B$27 -> 5423550 | H13: =H6*Inputs!$B$14*Inputs!$B$26*Inputs!$B$27 -> 5925150 | I13: =I6*Inputs!$B$14*Inputs!$B$26*Inputs!$B$27 -> 6426750 | ... AK13: =AK6*Inputs!$B$14*Inputs!$B$26*Inputs!$B$27 -> 28643450 | AL13: =SUM(B13:AK13) -> 479864000
A14: Comisiones reservas (Premium) | B14: =B7*Inputs!$B$15*Inputs!$B$26*Inputs!$B$27 -> 1170400 | C14: =C7*Inputs!$B$15*Inputs!$B$26*Inputs!$B$27 -> 1755600 | D14: =D7*Inputs!$B$15*Inputs!$B$26*Inputs!$B$27 -> 2340800 | E14: =E7*Inputs!$B$15*Inputs!$B$26*Inputs!$B$27 -> 2967800 | F14: =F7*Inputs!$B$15*Inputs!$B$26*Inputs!$B$27 -> 3636600 | G14: =G7*Inputs!$B$15*Inputs!$B$26*Inputs!$B$27 -> 4305400 | H14: =H7*Inputs!$B$15*Inputs!$B$26*Inputs!$B$27 -> 5016000 | I14: =I7*Inputs!$B$15*Inputs!$B$26*Inputs!$B$27 -> 5726600 | ... AK14: =AK7*Inputs!$B$15*Inputs!$B$26*Inputs!$B$27 -> 38623200 | AL14: =SUM(B14:AK14) -> 586621200
A15: Suscripciones Premium | B15: =B7*Inputs!$B$25 -> 921200 | C15: =C7*Inputs!$B$25 -> 1381800 | D15: =D7*Inputs!$B$25 -> 1842400 | E15: =E7*Inputs!$B$25 -> 2335900 | F15: =F7*Inputs!$B$25 -> 2862300 | G15: =G7*Inputs!$B$25 -> 3388700 | H15: =H7*Inputs!$B$25 -> 3948000 | I15: =I7*Inputs!$B$25 -> 4507300 | ... AK15: =AK7*Inputs!$B$25 -> 30399600 | AL15: =SUM(B15:AK15) -> 461718600
A16: Revenue B2B (publicidad + SaaS) | B16: =B8*Inputs!$B$29 -> 0 | C16: =C8*Inputs!$B$29 -> 0 | D16: =D8*Inputs!$B$29 -> 1400000 | E16: =E8*Inputs!$B$29 -> 2100000 | F16: =F8*Inputs!$B$29 -> 2800000 | G16: =G8*Inputs!$B$29 -> 3500000 | H16: =H8*Inputs!$B$29 -> 4200000 | I16: =I8*Inputs!$B$29 -> 4900000 | ... AK16: =AK8*Inputs!$B$29 -> 11900000 | AL16: =SUM(B16:AK16) -> 320600000
A17: TOTAL INGRESOS | B17: =SUM(B13:B16) -> 4725000 | C17: =SUM(C13:C16) -> 6387350 | D17: =SUM(D13:D16) -> 9407900 | E17: =SUM(E13:E16) -> 11782250 | F17: =SUM(F13:F16) -> 14210400 | G17: =SUM(G13:G16) -> 16617650 | H17: =SUM(H13:H16) -> 19089150 | I17: =SUM(I13:I16) -> 21560650 | ... AK17: =SUM(AK13:AK16) -> 109566250 | AL17: =SUM(B17:AK17) -> 1848803800
A19: Costo de Ventas (COGS - Variables)
A20: Costo pasarela Wompi | B20: =(B6*Inputs!$B$14+B7*Inputs!$B$15)*Inputs!$B$28 -> 1960140 | C20: =(C6*Inputs!$B$14+C7*Inputs!$B$15)*Inputs!$B$28 -> 2579415 | D20: =(D6*Inputs!$B$14+D7*Inputs!$B$15)*Inputs!$B$28 -> 3177150 | E20: =(E6*Inputs!$B$14+E7*Inputs!$B$15)*Inputs!$B$28 -> 3785655 | F20: =(F6*Inputs!$B$14+F7*Inputs!$B$15)*Inputs!$B$28 -> 4404930 | G20: =(G6*Inputs!$B$14+G7*Inputs!$B$15)*Inputs!$B$28 -> 5013435 | H20: =(H6*Inputs!$B$14+H7*Inputs!$B$15)*Inputs!$B$28 -> 5638095 | I20: =(I6*Inputs!$B$14+I7*Inputs!$B$15)*Inputs!$B$28 -> 6262755 | ... AK20: =(AK6*Inputs!$B$14+AK7*Inputs!$B$15)*Inputs!$B$28 -> 34663245 | AL20: =SUM(B20:AK20) -> 549571560
A21: Costo IA marginal (vLLM GPU) | B21: =(B6*Inputs!$B$18+B7*Inputs!$B$19)*Inputs!$B$20 -> 21280 | C21: =(C6*Inputs!$B$18+C7*Inputs!$B$19)*Inputs!$B$20 -> 29240 | D21: =(D6*Inputs!$B$18+D7*Inputs!$B$19)*Inputs!$B$20 -> 37040 | E21: =(E6*Inputs!$B$18+E7*Inputs!$B$19)*Inputs!$B$20 -> 45160 | F21: =(F6*Inputs!$B$18+F7*Inputs!$B$19)*Inputs!$B$20 -> 53600 | G21: =(G6*Inputs!$B$18+G7*Inputs!$B$19)*Inputs!$B$20 -> 61960 | H21: =(H6*Inputs!$B$18+H7*Inputs!$B$19)*Inputs!$B$20 -> 70680 | I21: =(I6*Inputs!$B$18+I7*Inputs!$B$19)*Inputs!$B$20 -> 79400 | ... AK21: =(AK6*Inputs!$B$18+AK7*Inputs!$B$19)*Inputs!$B$20 -> 479240 | AL21: =SUM(B21:AK21) -> 7450400
A22: APIs externas (variable por usuario) | B22: =B10*Inputs!$B$44 -> 201600 | C22: =C10*Inputs!$B$44 -> 254160 | D22: =D10*Inputs!$B$44 -> 303840 | E22: =E10*Inputs!$B$44 -> 352800 | F22: =F10*Inputs!$B$44 -> 401040 | G22: =G10*Inputs!$B$44 -> 447840 | H22: =H10*Inputs!$B$44 -> 494640 | I22: =I10*Inputs!$B$44 -> 541440 | ... AK22: =AK10*Inputs!$B$44 -> 2638800 | AL22: =SUM(B22:AK22) -> 43166880
A23: TOTAL COGS | B23: =SUM(B20:B22) -> 2183020 | C23: =SUM(C20:C22) -> 2862815 | D23: =SUM(D20:D22) -> 3518030 | E23: =SUM(E20:E22) -> 4183615 | F23: =SUM(F20:F22) -> 4859570 | G23: =SUM(G20:G22) -> 5523235 | H23: =SUM(H20:H22) -> 6203415 | I23: =SUM(I20:I22) -> 6883595 | ... AK23: =SUM(AK20:AK22) -> 37781285 | AL23: =SUM(B23:AK23) -> 600188840
A24: MARGEN BRUTO
A25: MARGEN BRUTO | B25: =B17-B23 -> 2541980 | C25: =C17-C23 -> 3524535 | D25: =D17-D23 -> 5889870 | E25: =E17-E23 -> 7598635 | F25: =F17-F23 -> 9350830 | G25: =G17-G23 -> 11094415 | H25: =H17-H23 -> 12885735 | I25: =I17-I23 -> 14677055 | ... AK25: =AK17-AK23 -> 71784965 | AL25: =SUM(B25:AK25) -> 1248614960
A26: % Margen Bruto | B26: =IFERROR(B25/B17,0) -> 0.53798519 | C26: =IFERROR(C25/C17,0) -> 0.55179926 | D26: =IFERROR(D25/D17,0) -> 0.62605576 | E26: =IFERROR(E25/E17,0) -> 0.64492223 | F26: =IFERROR(F25/F17,0) -> 0.65802722 | G26: =IFERROR(G25/G17,0) -> 0.6676284 | H26: =IFERROR(H25/H17,0) -> 0.67502927 | I26: =IFERROR(I25/I17,0) -> 0.68073342 | ... AL26: =IFERROR(AL25/AL17,0) -> 0.67536369
A28: Gastos Operativos (OPEX Fijo)
A29: Talento humano | B29: =Inputs!$B$40 -> 22675000 | C29: =Inputs!$B$40 -> 22675000 | D29: =Inputs!$B$40 -> 22675000 | E29: =Inputs!$B$40 -> 22675000 | F29: =Inputs!$B$40 -> 22675000 | G29: =Inputs!$B$40 -> 22675000 | H29: =Inputs!$B$40 -> 22675000 | I29: =Inputs!$B$40 -> 22675000 | ... AK29: =Inputs!$B$40 -> 22675000 | AL29: =SUM(B29:AK29) -> 816300000
A30: Infraestructura Cloud + GPU (Inputs) | B30: =Inputs!$B$41 -> 2602542 | C30: =Inputs!$B$41 -> 2602542 | D30: =Inputs!$B$41 -> 2602542 | E30: =Inputs!$B$41 -> 2602542 | F30: =Inputs!$B$41 -> 2602542 | G30: =Inputs!$B$41 -> 2602542 | H30: =Inputs!$B$41 -> 2602542 | I30: =Inputs!$B$41 -> 2602542 | ... AK30: =Inputs!$B$41 -> 2602542 | AL30: =SUM(B30:AK30) -> 93691512
A31: Marketing digital (base) | B31: =Inputs!$B$42 -> 1900000 | C31: =Inputs!$B$42 -> 1900000 | D31: =Inputs!$B$42 -> 1900000 | E31: =Inputs!$B$42 -> 1900000 | F31: =Inputs!$B$42 -> 1900000 | G31: =Inputs!$B$42 -> 1900000 | H31: =Inputs!$B$42 -> 1900000 | I31: =Inputs!$B$42 -> 1900000 | ... AK31: =Inputs!$B$42 -> 1900000 | AL31: =SUM(B31:AK31) -> 68400000
A32: APIs integradas (mínimo fijo mensual) | B32: =Inputs!$B$43 -> 2400000 | C32: =Inputs!$B$43 -> 2400000 | D32: =Inputs!$B$43 -> 2400000 | E32: =Inputs!$B$43 -> 2400000 | F32: =Inputs!$B$43 -> 2400000 | G32: =Inputs!$B$43 -> 2400000 | H32: =Inputs!$B$43 -> 2400000 | I32: =Inputs!$B$43 -> 2400000 | ... AK32: =Inputs!$B$43 -> 2400000 | AL32: =SUM(B32:AK32) -> 86400000
A33: CAC spend (adquisición) | B33: =B5*(1-Inputs!$B$9)*Inputs!$B$35+B5*Inputs!$B$9*Inputs!$B$36+B9*Inputs!$B$37 -> 1800000 | C33: =C5*(1-Inputs!$B$9)*Inputs!$B$35+C5*Inputs!$B$9*Inputs!$B$36+C9*Inputs!$B$37 -> 1890000 | D33: =D5*(1-Inputs!$B$9)*Inputs!$B$35+D5*Inputs!$B$9*Inputs!$B$36+D9*Inputs!$B$37 -> 5580000 | E33: =E5*(1-Inputs!$B$9)*Inputs!$B$35+E5*Inputs!$B$9*Inputs!$B$36+E9*Inputs!$B$37 -> 3888000 | F33: =F5*(1-Inputs!$B$9)*Inputs!$B$35+F5*Inputs!$B$9*Inputs!$B$36+F9*Inputs!$B$37 -> 3996000 | G33: =G5*(1-Inputs!$B$9)*Inputs!$B$35+G5*Inputs!$B$9*Inputs!$B$36+G9*Inputs!$B$37 -> 4104000 | H33: =H5*(1-Inputs!$B$9)*Inputs!$B$35+H5*Inputs!$B$9*Inputs!$B$36+H9*Inputs!$B$37 -> 4212000 | I33: =I5*(1-Inputs!$B$9)*Inputs!$B$35+I5*Inputs!$B$9*Inputs!$B$36+I9*Inputs!$B$37 -> 4338000 | ... AK33: =AK5*(1-Inputs!$B$9)*Inputs!$B$35+AK5*Inputs!$B$9*Inputs!$B$36+AK9*Inputs!$B$37 -> 11736000 | AL33: =SUM(B33:AK33) -> 235566000
A34: TOTAL OPEX | B34: =SUM(B29:B33) -> 31377542 | C34: =SUM(C29:C33) -> 31467542 | D34: =SUM(D29:D33) -> 35157542 | E34: =SUM(E29:E33) -> 33465542 | F34: =SUM(F29:F33) -> 33573542 | G34: =SUM(G29:G33) -> 33681542 | H34: =SUM(H29:H33) -> 33789542 | I34: =SUM(I29:I33) -> 33915542 | ... AK34: =SUM(AK29:AK33) -> 41313542 | AL34: =SUM(B34:AK34) -> 1300357512
A35: Rentabilidad
A36: EBITDA | B36: =B25-B34 -> -28835562 | C36: =C25-C34 -> -27943007 | D36: =D25-D34 -> -29267672 | E36: =E25-E34 -> -25866907 | F36: =F25-F34 -> -24222712 | G36: =G25-G34 -> -22587127 | H36: =H25-H34 -> -20903807 | I36: =I25-I34 -> -19238487 | ... AK36: =AK25-AK34 -> 30471423 | AL36: =SUM(B36:AK36) -> -51742552
A37: % EBITDA sobre ingresos (EBITDA Margin) | B37: =IFERROR(B36/B17,0) -> -6.1027644 | C37: =IFERROR(C36/C17,0) -> -4.3747418 | D37: =IFERROR(D36/D17,0) -> -3.1109676 | E37: =IFERROR(E36/E17,0) -> -2.1954132 | F37: =IFERROR(F36/F17,0) -> -1.7045764 | G37: =IFERROR(G36/G17,0) -> -1.3592251 | H37: =IFERROR(H36/H17,0) -> -1.0950622 | I37: =IFERROR(I36/I17,0) -> -0.89229624 | ... AL37: =IFERROR(AL36/AL17,0) -> -0.027987043
A38: Amortización CAPEX | B38: =Inputs!$B$47/Inputs!$B$48 -> 6057976.9 | C38: =Inputs!$B$47/Inputs!$B$48 -> 6057976.9 | D38: =Inputs!$B$47/Inputs!$B$48 -> 6057976.9 | E38: =Inputs!$B$47/Inputs!$B$48 -> 6057976.9 | F38: =Inputs!$B$47/Inputs!$B$48 -> 6057976.9 | G38: =Inputs!$B$47/Inputs!$B$48 -> 6057976.9 | H38: =Inputs!$B$47/Inputs!$B$48 -> 6057976.9 | I38: =Inputs!$B$47/Inputs!$B$48 -> 6057976.9 | ... AK38: =Inputs!$B$47/Inputs!$B$48 -> 6057976.9 | AL38: =SUM(B38:AK38) -> 2.1808717e+08
A39: EBIT | B39: =B36-B38 -> -34893539 | C39: =C36-C38 -> -34000984 | D39: =D36-D38 -> -35325649 | E39: =E36-E38 -> -31924884 | F39: =F36-F38 -> -30280689 | G39: =G36-G38 -> -28645104 | H39: =H36-H38 -> -26961784 | I39: =I36-I38 -> -25296464 | ... AK39: =AK36-AK38 -> 24413446 | AL39: =SUM(B39:AK39) -> -2.6982972e+08
A40: Impuesto de renta | B40: =IF(B39>0,B39*Inputs!$B$52,0) -> 0 | C40: =IF(C39>0,C39*Inputs!$B$52,0) -> 0 | D40: =IF(D39>0,D39*Inputs!$B$52,0) -> 0 | E40: =IF(E39>0,E39*Inputs!$B$52,0) -> 0 | F40: =IF(F39>0,F39*Inputs!$B$52,0) -> 0 | G40: =IF(G39>0,G39*Inputs!$B$52,0) -> 0 | H40: =IF(H39>0,H39*Inputs!$B$52,0) -> 0 | I40: =IF(I39>0,I39*Inputs!$B$52,0) -> 0 | ... AK40: =IF(AK39>0,AK39*Inputs!$B$52,0) -> 8056437.2 | AL40: =SUM(B40:AK40) -> 50086189
A41: UTILIDAD NETA | B41: =B39-B40 -> -34893539 | C41: =C39-C40 -> -34000984 | D41: =D39-D40 -> -35325649 | E41: =E39-E40 -> -31924884 | F41: =F39-F40 -> -30280689 | G41: =G39-G40 -> -28645104 | H41: =H39-H40 -> -26961784 | I41: =I39-I40 -> -25296464 | ... AK41: =AK39-AK40 -> 16357009 | AL41: =SUM(B41:AK41) -> -3.1991591e+08
A42: % Margen Neto | B42: =IFERROR(B41/B17,0) -> -7.384876 | C42: =IFERROR(C41/C17,0) -> -5.3231753 | D42: =IFERROR(D41/D17,0) -> -3.754892 | E42: =IFERROR(E41/E17,0) -> -2.7095745 | F42: =IFERROR(F41/F17,0) -> -2.1308822 | G42: =IFERROR(G41/G17,0) -> -1.7237759 | H42: =IFERROR(H41/H17,0) -> -1.4124141 | I42: =IFERROR(I41/I17,0) -> -1.17327 | ... AL42: =IFERROR(AL41/AL17,0) -> -0.1730394

Sheet FC Proyecto
A1: Flujo de Caja del PROYECTO - sin inflación, sin financiación, sin impuestos
A3: Concepto (COP) | B3: Mes 1 | C3: Mes 2 | D3: Mes 3 | E3: Mes 4 | F3: Mes 5 | G3: Mes 6 | H3: Mes 7 | I3: Mes 8 | J3: Mes 9 | K3: Mes 10 | L3: Mes 11 | M3: Mes 12 | N3: Mes 13 | O3: Mes 14 | P3: Mes 15 | Q3: Mes 16 | R3: Mes 17 | S3: Mes 18 | T3: Mes 19 | U3: Mes 20 | V3: Mes 21 | W3: Mes 22 | X3: Mes 23 | Y3: Mes 24 | Z3: Mes 25 | AA3: Mes 26 | AB3: Mes 27 | AC3: Mes 28 | AD3: Mes 29 | AE3: Mes 30 | AF3: Mes 31 | AG3: Mes 32 | AH3: Mes 33 | AI3: Mes 34 | AJ3: Mes 35 | AK3: Mes 36
A4: EBITDA (PyG) | B4: ='P&G 36 Meses'!B36 -> -28835562 | C4: ='P&G 36 Meses'!C36 -> -27943007 | D4: ='P&G 36 Meses'!D36 -> -29267672 | E4: ='P&G 36 Meses'!E36 -> -25866907 | F4: ='P&G 36 Meses'!F36 -> -24222712 | G4: ='P&G 36 Meses'!G36 -> -22587127 | H4: ='P&G 36 Meses'!H36 -> -20903807 | I4: ='P&G 36 Meses'!I36 -> -19238487 | ... AK4: ='P&G 36 Meses'!AK36 -> 30471423
A5: (-) Impuestos (excluidos) | B5: 0 | C5: 0 | D5: 0 | E5: 0 | F5: 0 | G5: 0 | H5: 0 | I5: 0 | J5: 0 | K5: 0 | L5: 0 | M5: 0 | N5: 0 | O5: 0 | P5: 0 | Q5: 0 | R5: 0 | S5: 0 | T5: 0 | U5: 0 | V5: 0 | W5: 0 | X5: 0 | Y5: 0 | Z5: 0 | AA5: 0 | AB5: 0 | AC5: 0 | AD5: 0 | AE5: 0 | AF5: 0 | AG5: 0 | AH5: 0 | AI5: 0 | AJ5: 0 | AK5: 0
